Workbook

Sheet 0922
I1: 담당 | J1: 검토 | K1: 확인
A2: (김포)생산공급망 업무일지 | I2: 최용화 | J2: 윤경용 | N2: 초록색상 지우기와 기재 금지
A4: 날짜 | B4: 46287
A6: ■ 제품포장작업
A7: 품명 | B7: 용량/규격 | C7: 수량 | D7: 박스 | E7: 작업시간 | F7: 투입인원수 | G7: 총작업시간 | H7: LINE/구분 | I7: 비고(LOT/NO) | J7: 카테고리 | K7: 작업공수 | L7: 작업자 | M7: 시작 | N7: 끝 | O7: 작업시간
A8: 2AA40041 / 스탠다드 100%합성엔진오일 5W30 | 1L | B8: =IFERROR(__xludf.DUMMYFUNCTION("IFERROR(REGEXEXTRACT(A8,""\| (.+)$""),"""") "),"1L") -> 1L | C8: 1200 | D8: 100 | E8: 2.5 | F8: 4 | G8: =IF(OR(E8="",F8=""),"",E8*F8) -> 10 | H8: 자동 | I8: 260723 | J8: 엔진오일 | K8: =IF(OR(E8="",F8=""),"",(E8*F8)/7.5) -> 1.3333333 | O8: =IF(OR(M8="",N8=""),"",_xlfn.CEILING.MATH((N8-M8-(MEDIAN(N8,"13:00","12:00")-MEDIAN(M8,"13:00","12:00"))-(MEDIAN(N8,"16:30","16:00")-MEDIAN(M8,"16:30","16:00"))),"0:30")*24)
A9: 2AJ40047 / 인젝션 펌프 청소유 | 4L | B9: =IFERROR(__xludf.DUMMYFUNCTION("IFERROR(REGEXEXTRACT(A9,""\| (.+)$""),"""") "),"4L") -> 4L | C9: 152 | D9: 38 | E9: 1.5 | F9: 4 | G9: =IF(OR(E9="",F9=""),"",E9*F9) -> 6 | H9: 수동1 | I9: 260922 | J9: 기타 | K9: =IF(OR(E9="",F9=""),"",(E9*F9)/7.5) -> 0.8 | O9: =IF(OR(M9="",N9=""),"",_xlfn.CEILING.MATH((N9-M9-(MEDIAN(N9,"13:00","12:00")-MEDIAN(M9,"13:00","12:00"))-(MEDIAN(N9,"16:30","16:00")-MEDIAN(M9,"16:30","16:00"))),"0:30")*24)
A10: 2AJ40047 / 인젝션 펌프 청소유 | 4L | B10: =IFERROR(__xludf.DUMMYFUNCTION("IFERROR(REGEXEXTRACT(A10,""\| (.+)$""),"""") "),"4L") -> 4L | C10: 408 | D10: 102 | E10: 3 | F10: 3 | G10: =IF(OR(E10="",F10=""),"",E10*F10) -> 9 | H10: 수동1 | I10: 260922 | J10: 기타 | K10: =IF(OR(E10="",F10=""),"",(E10*F10)/7.5) -> 1.2 | O10: =IF(OR(M10="",N10=""),"",_xlfn.CEILING.MATH((N10-M10-(MEDIAN(N10,"13:00","12:00")-MEDIAN(M10,"13:00","12:00"))-(MEDIAN(N10,"16:30","16:00")-MEDIAN(M10,"16:30","16:00"))),"0:30")*24)
B11: =IFERROR(__xludf.DUMMYFUNCTION("IFERROR(REGEXEXTRACT(A11,""\| (.+)$""),"""") "),"") | G11: =IF(OR(E11="",F11=""),"",E11*F11) | K11: =IF(OR(E11="",F11=""),"",(E11*F11)/7.5) | O11: =IF(OR(M11="",N11=""),"",_xlfn.CEILING.MATH((N11-M11-(MEDIAN(N11,"13:00","12:00")-MEDIAN(M11,"13:00","12:00"))-(MEDIAN(N11,"16:30","16:00")-MEDIAN(M11,"16:30","16:00"))),"0:30")*24)
B12: =IFERROR(__xludf.DUMMYFUNCTION("IFERROR(REGEXEXTRACT(A12,""\| (.+)$""),"""") "),"") | G12: =IF(OR(E12="",F12=""),"",E12*F12) | K12: =IF(OR(E12="",F12=""),"",(E12*F12)/7.5) | O12: =IF(OR(M12="",N12=""),"",_xlfn.CEILING.MATH((N12-M12-(MEDIAN(N12,"13:00","12:00")-MEDIAN(M12,"13:00","12:00"))-(MEDIAN(N12,"16:30","16:00")-MEDIAN(M12,"16:30","16:00"))),"0:30")*24)
B13: =IFERROR(__xludf.DUMMYFUNCTION("IFERROR(REGEXEXTRACT(A13,""\| (.+)$""),"""") "),"") | G13: =IF(OR(E13="",F13=""),"",E13*F13) | K13: =IF(OR(E13="",F13=""),"",(E13*F13)/7.5) | O13: =IF(OR(M13="",N13=""),"",_xlfn.CEILING.MATH((N13-M13-(MEDIAN(N13,"13:00","12:00")-MEDIAN(M13,"13:00","12:00"))-(MEDIAN(N13,"16:30","16:00")-MEDIAN(M13,"16:30","16:00"))),"0:30")*24)
B14: =IFERROR(__xludf.DUMMYFUNCTION("IFERROR(REGEXEXTRACT(A14,""\| (.+)$""),"""") "),"") | G14: =IF(OR(E14="",F14=""),"",E14*F14) | K14: =IF(OR(E14="",F14=""),"",(E14*F14)/7.5) | O14: =IF(OR(M14="",N14=""),"",_xlfn.CEILING.MATH((N14-M14-(MEDIAN(N14,"13:00","12:00")-MEDIAN(M14,"13:00","12:00"))-(MEDIAN(N14,"16:30","16:00")-MEDIAN(M14,"16:30","16:00"))),"0:30")*24)
B15: =IFERROR(__xludf.DUMMYFUNCTION("IFERROR(REGEXEXTRACT(A15,""\| (.+)$""),"""") "),"") | G15: =IF(OR(E15="",F15=""),"",E15*F15) | K15: =IF(OR(E15="",F15=""),"",(E15*F15)/7.5) | O15: =IF(OR(M15="",N15=""),"",_xlfn.CEILING.MATH((N15-M15-(MEDIAN(N15,"13:00","12:00")-MEDIAN(M15,"13:00","12:00"))-(MEDIAN(N15,"16:30","16:00")-MEDIAN(M15,"16:30","16:00"))),"0:30")*24)
B16: =IFERROR(__xludf.DUMMYFUNCTION("IFERROR(REGEXEXTRACT(A16,""\| (.+)$""),"""") "),"") | G16: =IF(OR(E16="",F16=""),"",E16*F16) | K16: =IF(OR(E16="",F16=""),"",(E16*F16)/7.5) | O16: =IF(OR(M16="",N16=""),"",_xlfn.CEILING.MATH((N16-M16-(MEDIAN(N16,"13:00","12:00")-MEDIAN(M16,"13:00","12:00"))-(MEDIAN(N16,"16:30","16:00")-MEDIAN(M16,"16:30","16:00"))),"0:30")*24)
B17: =IFERROR(__xludf.DUMMYFUNCTION("IFERROR(REGEXEXTRACT(A17,""\| (.+)$""),"""") "),"") | G17: =IF(OR(E17="",F17=""),"",E17*F17) | K17: =IF(OR(E17="",F17=""),"",(E17*F17)/7.5)
A18: 총수량 | C18: =SUM(C8:C17) -> 1760 | D18: =SUM(D8:D17) -> 240 | E18: =SUM(E8:E17) -> 7 | F18: =IFERROR(G18/E18, 0) -> 3.5714286 | G18: =SUM(G8:G17) -> 25 | K18: =SUM(K8:K14) -> 3.3333333
A20: ■ 라벨부착작업
A21: 품명 | B21: 용량/규격 | C21: 수량 | D21: 박스 | E21: 작업시간 | F21: 투입인원수 | G21: 총작업시간 | H21: LINE/구분 | I21: 비고(LOT/NO) | J21: 카테고리 | K21: 작업공수 | M21: 시작 | N21: 끝 | O21: 작업시간
B22: =IFERROR(__xludf.DUMMYFUNCTION("IFERROR(REGEXEXTRACT(A22,""\| (.+)$""),"""") "),"") | G22: =IF(OR(E22="",F22=""),"",E22*F22) | K22: =IF(OR(E22="",F22=""),"",(E22*F22)/7.5) | O22: =IF(OR(M22="",N22=""),"",_xlfn.CEILING.MATH((N22-M22-(MEDIAN(N22,"13:00","12:00")-MEDIAN(M22,"13:00","12:00"))-(MEDIAN(N22,"16:30","16:00")-MEDIAN(M22,"16:30","16:00"))),"0:30")*24)
B23: =IFERROR(__xludf.DUMMYFUNCTION("IFERROR(REGEXEXTRACT(A23,""\| (.+)$""),"""") "),"") | G23: =IF(OR(E23="",F23=""),"",E23*F23) | K23: =IF(OR(E23="",F23=""),"",(E23*F23)/7.5) | O23: =IF(OR(M23="",N23=""),"",_xlfn.CEILING.MATH((N23-M23-(MEDIAN(N23,"13:00","12:00")-MEDIAN(M23,"13:00","12:00"))-(MEDIAN(N23,"16:30","16:00")-MEDIAN(M23,"16:30","16:00"))),"0:30")*24)
B24: =IFERROR(__xludf.DUMMYFUNCTION("IFERROR(REGEXEXTRACT(A24,""\| (.+)$""),"""") "),"") | G24: =IF(OR(E24="",F24=""),"",E24*F24) | K24: =IF(OR(E24="",F24=""),"",(E24*F24)/7.5) | O24: =IF(OR(M24="",N24=""),"",_xlfn.CEILING.MATH((N24-M24-(MEDIAN(N24,"13:00","12:00")-MEDIAN(M24,"13:00","12:00"))-(MEDIAN(N24,"16:30","16:00")-MEDIAN(M24,"16:30","16:00"))),"0:30")*24)
B25: =IFERROR(__xludf.DUMMYFUNCTION("IFERROR(REGEXEXTRACT(A25,""\| (.+)$""),"""") "),"") | G25: =IF(OR(E25="",F25=""),"",E25*F25) | K25: =IF(OR(E25="",F25=""),"",(E25*F25)/7.5) | O25: =IF(OR(M25="",N25=""),"",_xlfn.CEILING.MATH((N25-M25-(MEDIAN(N25,"13:00","12:00")-MEDIAN(M25,"13:00","12:00"))-(MEDIAN(N25,"16:30","16:00")-MEDIAN(M25,"16:30","16:00"))),"0:30")*24)
B26: =IFERROR(__xludf.DUMMYFUNCTION("IFERROR(REGEXEXTRACT(A26,""\| (.+)$""),"""") "),"") | G26: =IF(OR(E26="",F26=""),"",E26*F26) | K26: =IF(OR(E26="",F26=""),"",(E26*F26)/7.5) | O26: =IF(OR(M26="",N26=""),"",_xlfn.CEILING.MATH((N26-M26-(MEDIAN(N26,"13:00","12:00")-MEDIAN(M26,"13:00","12:00"))-(MEDIAN(N26,"16:30","16:00")-MEDIAN(M26,"16:30","16:00"))),"0:30")*24)
A27: 총수량 | C27: =SUM(C22:C26) -> 0 | D27: =SUM(D22:D26) -> 0 | E27: =SUM(E22:E26) -> 0 | F27: =IFERROR(G27/E27, 0) -> 0 | G27: =SUM(G22:G26) -> 0 | K27: =SUM(K22:K26) -> 0
A29: ■ 원액생산작업
A30: 품명 | B30: 용량/규격 | C30: 수량 | D30: 포장 | E30: 작업시간 | F30: 투입인원수 | G30: 총작업시간 | H30: LINE/구분 | I30: 비고(LOT/NO) | J30: 카테고리 | K30: 작업공수
A31: 5AA40008 / ODM 5W30 | B31: L | C31: 1694 | D31: TOTE | E31: 2 | F31: 1 | G31: =IF(OR(E31="",F31=""),"",E31*F31) -> 2 | H31: BT-2 | I31: G260922-021 | J31: 엔진오일 | K31: =IF(OR(E31="",F31=""),"",(E31*F31)/7.5) -> 0.26666667
G32: =IF(OR(E32="",F32=""),"",E32*F32) | K32: =IF(OR(E32="",F32=""),"",(E32*F32)/7.5)
G33: =IF(OR(E33="",F33=""),"",E33*F33) | K33: =IF(OR(E33="",F33=""),"",(E33*F33)/7.5)
G34: =IF(OR(E34="",F34=""),"",E34*F34) | K34: =IF(OR(E34="",F34=""),"",(E34*F34)/7.5)
G35: =IF(OR(E35="",F35=""),"",E35*F35) | K35: =IF(OR(E35="",F35=""),"",(E35*F35)/7.5)
A36: 총수량 | C36: =SUM(C31:C35) -> 1694 | E36: =SUM(E28:E35) -> 2 | F36: =IFERROR(G36/E36, 0) -> 1 | G36: =SUM(G26:G35) -> 2 | K36: =SUM(K31:K35) -> 0.26666667
A38: ■ 출고내역
A39: 품명 | B39: 용량/규격 | C39: 수량 | D39: 박스 | E39: 거래처 | G39: 확인자 | H39: 운송 | I39: 비고
A40: 2AA40053 / 아디노 100%합성엔진오일 5W30 | 1L | B40: =IFERROR(__xludf.DUMMYFUNCTION("IFERROR(REGEXEXTRACT(A40,""\| (.+)$""),"""") "),"1L") -> 1L | C40: 1440 | D40: 120 | E40: 마하나임코리아 | G40: 윤경용 | H40: 용차 | I40: 운송료:55,000 VAT포함
B41: =IFERROR(__xludf.DUMMYFUNCTION("IFERROR(REGEXEXTRACT(A41,""\| (.+)$""),"""") "),"")
B42: =IFERROR(__xludf.DUMMYFUNCTION("IFERROR(REGEXEXTRACT(A42,""\| (.+)$""),"""") "),"")
B43: =IFERROR(__xludf.DUMMYFUNCTION("IFERROR(REGEXEXTRACT(A43,""\| (.+)$""),"""") "),"")
B47: =IFERROR(__xludf.DUMMYFUNCTION("IFERROR(REGEXEXTRACT(A47,""\| (.+)$""),"""") "),"")
A48: 총수량 | C48: =SUM(C40:C47) -> 1440
...

Sheet 0921
I1: 담당 | J1: 검토 | K1: 확인
A2: (김포)생산공급망 업무일지 | I2: 최용화 | J2: 윤경용 | N2: 초록색상 지우기와 기재 금지
A4: 날짜 | B4: 46286
A6: ■ 제품포장작업
A7: 품명 | B7: 용량/규격 | C7: 수량 | D7: 박스 | E7: 작업시간 | F7: 투입인원수 | G7: 총작업시간 | H7: LINE/구분 | I7: 비고(LOT/NO) | J7: 카테고리 | K7: 작업공수 | L7: 작업자 | M7: 시작 | N7: 끝 | O7: 작업시간
A8: 1AA40002 / 썸오일 100% 합성엔진오일 0W20 | 1L | B8: =IFERROR(__xludf.DUMMYFUNCTION("IFERROR(REGEXEXTRACT(A8,""\| (.+)$""),"""") "),"1L") -> 1L | C8: 720 | D8: 60 | E8: 2.5 | F8: 3 | G8: =IF(OR(E8="",F8=""),"",E8*F8) -> 7.5 | H8: 자동 | I8: 260921 | J8: 엔진오일 | K8: =IF(OR(E8="",F8=""),"",(E8*F8)/7.5) -> 1 | O8: =IF(OR(M8="",N8=""),"",_xlfn.CEILING.MATH((N8-M8-(MEDIAN(N8,"13:00","12:00")-MEDIAN(M8,"13:00","12:00"))-(MEDIAN(N8,"16:30","16:00")-MEDIAN(M8,"16:30","16:00"))),"0:30")*24)
A9: 2AA40001 / GT Formula 엔진오일 PAO 0W20 | 1L | B9: =IFERROR(__xludf.DUMMYFUNCTION("IFERROR(REGEXEXTRACT(A9,""\| (.+)$""),"""") "),"1L") -> 1L | C9: 1152 | D9: 96 | E9: 2 | F9: 4 | G9: =IF(OR(E9="",F9=""),"",E9*F9) -> 8 | H9: 자동 | J9: 엔진오일 | K9: =IF(OR(E9="",F9=""),"",(E9*F9)/7.5) -> 1.0666667 | O9: =IF(OR(M9="",N9=""),"",_xlfn.CEILING.MATH((N9-M9-(MEDIAN(N9,"13:00","12:00")-MEDIAN(M9,"13:00","12:00"))-(MEDIAN(N9,"16:30","16:00")-MEDIAN(M9,"16:30","16:00"))),"0:30")*24)
A10: 2AA40041 / 스탠다드 100%합성엔진오일 5W30 | 1L | B10: =IFERROR(__xludf.DUMMYFUNCTION("IFERROR(REGEXEXTRACT(A10,""\| (.+)$""),"""") "),"1L") -> 1L | C10: 240 | D10: 20 | E10: 1 | F10: 4 | G10: =IF(OR(E10="",F10=""),"",E10*F10) -> 4 | H10: 자동 | I10: 260723 | J10: 엔진오일 | K10: =IF(OR(E10="",F10=""),"",(E10*F10)/7.5) -> 0.53333333 | O10: =IF(OR(M10="",N10=""),"",_xlfn.CEILING.MATH((N10-M10-(MEDIAN(N10,"13:00","12:00")-MEDIAN(M10,"13:00","12:00"))-(MEDIAN(N10,"16:30","16:00")-MEDIAN(M10,"16:30","16:00"))),"0:30")*24)
B11: =IFERROR(__xludf.DUMMYFUNCTION("IFERROR(REGEXEXTRACT(A11,""\| (.+)$""),"""") "),"") | G11: =IF(OR(E11="",F11=""),"",E11*F11) | K11: =IF(OR(E11="",F11=""),"",(E11*F11)/7.5) | O11: =IF(OR(M11="",N11=""),"",_xlfn.CEILING.MATH((N11-M11-(MEDIAN(N11,"13:00","12:00")-MEDIAN(M11,"13:00","12:00"))-(MEDIAN(N11,"16:30","16:00")-MEDIAN(M11,"16:30","16:00"))),"0:30")*24)
B12: =IFERROR(__xludf.DUMMYFUNCTION("IFERROR(REGEXEXTRACT(A12,""\| (.+)$""),"""") "),"") | G12: =IF(OR(E12="",F12=""),"",E12*F12) | K12: =IF(OR(E12="",F12=""),"",(E12*F12)/7.5) | O12: =IF(OR(M12="",N12=""),"",_xlfn.CEILING.MATH((N12-M12-(MEDIAN(N12,"13:00","12:00")-MEDIAN(M12,"13:00","12:00"))-(MEDIAN(N12,"16:30","16:00")-MEDIAN(M12,"16:30","16:00"))),"0:30")*24)
B13: =IFERROR(__xludf.DUMMYFUNCTION("IFERROR(REGEXEXTRACT(A13,""\| (.+)$""),"""") "),"") | G13: =IF(OR(E13="",F13=""),"",E13*F13) | K13: =IF(OR(E13="",F13=""),"",(E13*F13)/7.5) | O13: =IF(OR(M13="",N13=""),"",_xlfn.CEILING.MATH((N13-M13-(MEDIAN(N13,"13:00","12:00")-MEDIAN(M13,"13:00","12:00"))-(MEDIAN(N13,"16:30","16:00")-MEDIAN(M13,"16:30","16:00"))),"0:30")*24)
B14: =IFERROR(__xludf.DUMMYFUNCTION("IFERROR(REGEXEXTRACT(A14,""\| (.+)$""),"""") "),"") | G14: =IF(OR(E14="",F14=""),"",E14*F14) | K14: =IF(OR(E14="",F14=""),"",(E14*F14)/7.5) | O14: =IF(OR(M14="",N14=""),"",_xlfn.CEILING.MATH((N14-M14-(MEDIAN(N14,"13:00","12:00")-MEDIAN(M14,"13:00","12:00"))-(MEDIAN(N14,"16:30","16:00")-MEDIAN(M14,"16:30","16:00"))),"0:30")*24)
B15: =IFERROR(__xludf.DUMMYFUNCTION("IFERROR(REGEXEXTRACT(A15,""\| (.+)$""),"""") "),"") | G15: =IF(OR(E15="",F15=""),"",E15*F15) | K15: =IF(OR(E15="",F15=""),"",(E15*F15)/7.5) | O15: =IF(OR(M15="",N15=""),"",_xlfn.CEILING.MATH((N15-M15-(MEDIAN(N15,"13:00","12:00")-MEDIAN(M15,"13:00","12:00"))-(MEDIAN(N15,"16:30","16:00")-MEDIAN(M15,"16:30","16:00"))),"0:30")*24)
B16: =IFERROR(__xludf.DUMMYFUNCTION("IFERROR(REGEXEXTRACT(A16,""\| (.+)$""),"""") "),"") | G16: =IF(OR(E16="",F16=""),"",E16*F16) | K16: =IF(OR(E16="",F16=""),"",(E16*F16)/7.5) | O16: =IF(OR(M16="",N16=""),"",_xlfn.CEILING.MATH((N16-M16-(MEDIAN(N16,"13:00","12:00")-MEDIAN(M16,"13:00","12:00"))-(MEDIAN(N16,"16:30","16:00")-MEDIAN(M16,"16:30","16:00"))),"0:30")*24)
B17: =IFERROR(__xludf.DUMMYFUNCTION("IFERROR(REGEXEXTRACT(A17,""\| (.+)$""),"""") "),"") | G17: =IF(OR(E17="",F17=""),"",E17*F17) | K17: =IF(OR(E17="",F17=""),"",(E17*F17)/7.5)
A18: 총수량 | C18: =SUM(C8:C17) -> 2112 | D18: =SUM(D8:D17) -> 176 | E18: =SUM(E8:E17) -> 5.5 | F18: =IFERROR(G18/E18, 0) -> 3.5454545 | G18: =SUM(G8:G17) -> 19.5 | K18: =SUM(K8:K14) -> 2.6
A20: ■ 라벨부착작업
A21: 품명 | B21: 용량/규격 | C21: 수량 | D21: 박스 | E21: 작업시간 | F21: 투입인원수 | G21: 총작업시간 | H21: LINE/구분 | I21: 비고(LOT/NO) | J21: 카테고리 | K21: 작업공수 | M21: 시작 | N21: 끝 | O21: 작업시간
A22: DA020664 / 프로텍 브레이크액 DOT-4+ 1L 라벨 | 81*111 | B22: =IFERROR(__xludf.DUMMYFUNCTION("IFERROR(REGEXEXTRACT(A22,""\| (.+)$""),"""") "),"81*111") -> 81*111 | C22: 1106 | E22: 1.3 | F22: 3 | G22: =IF(OR(E22="",F22=""),"",E22*F22) -> 3.9 | H22: 자동B | J22: 브레이크액 | K22: =IF(OR(E22="",F22=""),"",(E22*F22)/7.5) -> 0.52 | O22: =IF(OR(M22="",N22=""),"",_xlfn.CEILING.MATH((N22-M22-(MEDIAN(N22,"13:00","12:00")-MEDIAN(M22,"13:00","12:00"))-(MEDIAN(N22,"16:30","16:00")-MEDIAN(M22,"16:30","16:00"))),"0:30")*24)
A23: DA020669 / 프로텍 브레이크액 DOT-4+ LV 1L 라벨 | 81*111 | B23: =IFERROR(__xludf.DUMMYFUNCTION("IFERROR(REGEXEXTRACT(A23,""\| (.+)$""),"""") "),"81*111") -> 81*111 | C23: 599 | E23: 0.5 | F23: 3 | G23: =IF(OR(E23="",F23=""),"",E23*F23) -> 1.5 | H23: 수동B | J23: 브레이크액 | K23: =IF(OR(E23="",F23=""),"",(E23*F23)/7.5) -> 0.2 | O23: =IF(OR(M23="",N23=""),"",_xlfn.CEILING.MATH((N23-M23-(MEDIAN(N23,"13:00","12:00")-MEDIAN(M23,"13:00","12:00"))-(MEDIAN(N23,"16:30","16:00")-MEDIAN(M23,"16:30","16:00"))),"0:30")*24)
B24: =IFERROR(__xludf.DUMMYFUNCTION("IFERROR(REGEXEXTRACT(A24,""\| (.+)$""),"""") "),"") | G24: =IF(OR(E24="",F24=""),"",E24*F24) | K24: =IF(OR(E24="",F24=""),"",(E24*F24)/7.5) | O24: =IF(OR(M24="",N24=""),"",_xlfn.CEILING.MATH((N24-M24-(MEDIAN(N24,"13:00","12:00")-MEDIAN(M24,"13:00","12:00"))-(MEDIAN(N24,"16:30","16:00")-MEDIAN(M24,"16:30","16:00"))),"0:30")*24)
B25: =IFERROR(__xludf.DUMMYFUNCTION("IFERROR(REGEXEXTRACT(A25,""\| (.+)$""),"""") "),"") | G25: =IF(OR(E25="",F25=""),"",E25*F25) | K25: =IF(OR(E25="",F25=""),"",(E25*F25)/7.5) | O25: =IF(OR(M25="",N25=""),"",_xlfn.CEILING.MATH((N25-M25-(MEDIAN(N25,"13:00","12:00")-MEDIAN(M25,"13:00","12:00"))-(MEDIAN(N25,"16:30","16:00")-MEDIAN(M25,"16:30","16:00"))),"0:30")*24)
B26: =IFERROR(__xludf.DUMMYFUNCTION("IFERROR(REGEXEXTRACT(A26,""\| (.+)$""),"""") "),"") | G26: =IF(OR(E26="",F26=""),"",E26*F26) | K26: =IF(OR(E26="",F26=""),"",(E26*F26)/7.5) | O26: =IF(OR(M26="",N26=""),"",_xlfn.CEILING.MATH((N26-M26-(MEDIAN(N26,"13:00","12:00")-MEDIAN(M26,"13:00","12:00"))-(MEDIAN(N26,"16:30","16:00")-MEDIAN(M26,"16:30","16:00"))),"0:30")*24)
A27: 총수량 | C27: =SUM(C22:C26) -> 1705 | D27: =SUM(D22:D26) -> 0 | E27: =SUM(E22:E26) -> 1.8 | F27: =IFERROR(G27/E27, 0) -> 3 | G27: =SUM(G22:G26) -> 5.4 | K27: =SUM(K22:K26) -> 0.72
A29: ■ 원액생산작업
A30: 품명 | B30: 용량/규격 | C30: 수량 | D30: 포장 | E30: 작업시간 | F30: 투입인원수 | G30: 총작업시간 | H30: LINE/구분 | I30: 비고(LOT/NO) | J30: 카테고리 | K30: 작업공수
A31: 5AA40001 / ODM 0W20 GD | B31: L | C31: 2020.8 | D31: TOTE | E31: 1.5 | F31: 1 | G31: =IF(OR(E31="",F31=""),"",E31*F31) -> 1.5 | H31: BT-2 | I31: G260921-021 | J31: 엔진오일 | K31: =IF(OR(E31="",F31=""),"",(E31*F31)/7.5) -> 0.2
A32: 5AB40005 / 엑스퍼트 엔진코팅제 | B32: L | C32: 1000 | D32: TOTE | E32: 2 | F32: 2 | G32: =IF(OR(E32="",F32=""),"",E32*F32) -> 4 | H32: BT-2 | I32: G260921-022 | J32: 엔진코팅제 | K32: =IF(OR(E32="",F32=""),"",(E32*F32)/7.5) -> 0.53333333
G33: =IF(OR(E33="",F33=""),"",E33*F33) | K33: =IF(OR(E33="",F33=""),"",(E33*F33)/7.5)
G34: =IF(OR(E34="",F34=""),"",E34*F34) | K34: =IF(OR(E34="",F34=""),"",(E34*F34)/7.5)
G35: =IF(OR(E35="",F35=""),"",E35*F35) | K35: =IF(OR(E35="",F35=""),"",(E35*F35)/7.5)
A36: 총수량 | C36: =SUM(C31:C35) -> 3020.8 | E36: =SUM(E28:E35) -> 3.5 | F36: =IFERROR(G36/E36, 0) -> 3.1142857 | G36: =SUM(G26:G35) -> 10.9 | K36: =SUM(K31:K35) -> 0.73333333
A38: ■ 출고내역
A39: 품명 | B39: 용량/규격 | C39: 수량 | D39: 박스 | E39: 거래처 | G39: 확인자 | H39: 운송 | I39: 비고
B40: =IFERROR(__xludf.DUMMYFUNCTION("IFERROR(REGEXEXTRACT(A40,""\| (.+)$""),"""") "),"")
B41: =IFERROR(__xludf.DUMMYFUNCTION("IFERROR(REGEXEXTRACT(A41,""\| (.+)$""),"""") "),"")
B42: =IFERROR(__xludf.DUMMYFUNCTION("IFERROR(REGEXEXTRACT(A42,""\| (.+)$""),"""") "),"")
B43: =IFERROR(__xludf.DUMMYFUNCTION("IFERROR(REGEXEXTRACT(A43,""\| (.+)$""),"""") "),"")
B47: =IFERROR(__xludf.DUMMYFUNCTION("IFERROR(REGEXEXTRACT(A47,""\| (.+)$""),"""") "),"")
A48: 총수량 | C48: =SUM(C40:C47) -> 0
...

Sheet 0918
I1: 담당 | J1: 검토 | K1: 확인
A2: (김포)생산공급망 업무일지 | I2: 최용화 | J2: 윤경용 | N2: 초록색상 지우기와 기재 금지
A4: 날짜 | B4: 46283
A6: ■ 제품포장작업
A7: 품명 | B7: 용량/규격 | C7: 수량 | D7: 박스 | E7: 작업시간 | F7: 투입인원수 | G7: 총작업시간 | H7: LINE/구분 | I7: 비고(LOT/NO) | J7: 카테고리 | K7: 작업공수 | L7: 작업자 | M7: 시작 | N7: 끝 | O7: 작업시간
A8: 2AA40003 / GT Formula 엔진오일 PAO 5W30 | 1L | B8: =IFERROR(__xludf.DUMMYFUNCTION("IFERROR(REGEXEXTRACT(A8,""\| (.+)$""),"""") "),"1L") -> 1L | C8: 540 | D8: 45 | E8: 1.5 | F8: 3 | G8: =IF(OR(E8="",F8=""),"",E8*F8) -> 4.5 | H8: 자동 | J8: 엔진오일 | K8: =IF(OR(E8="",F8=""),"",(E8*F8)/7.5) -> 0.6 | L8: 정화순, 윤상모, 김백철, 김세중 | O8: =IF(OR(M8="",N8=""),"",_xlfn.CEILING.MATH((N8-M8-(MEDIAN(N8,"13:00","12:00")-MEDIAN(M8,"13:00","12:00"))-(MEDIAN(N8,"16:30","16:00")-MEDIAN(M8,"16:30","16:00"))),"0:30")*24)
A9: 1AA40012 / 썸오일 100% 합성엔진오일 4T 5W40 | 1L | B9: =IFERROR(__xludf.DUMMYFUNCTION("IFERROR(REGEXEXTRACT(A9,""\| (.+)$""),"""") "),"1L") -> 1L | C9: 432 | D9: 36 | E9: 2.5 | F9: 3 | G9: =IF(OR(E9="",F9=""),"",E9*F9) -> 7.5 | H9: 자동 | J9: 엔진오일 | K9: =IF(OR(E9="",F9=""),"",(E9*F9)/7.5) -> 1 | L9: 정화순, 윤상모, 김세중 | O9: =IF(OR(M9="",N9=""),"",_xlfn.CEILING.MATH((N9-M9-(MEDIAN(N9,"13:00","12:00")-MEDIAN(M9,"13:00","12:00"))-(MEDIAN(N9,"16:30","16:00")-MEDIAN(M9,"16:30","16:00"))),"0:30")*24)
A10: 1AA40012 / 썸오일 100% 합성엔진오일 4T 5W40 | 1L | B10: =IFERROR(__xludf.DUMMYFUNCTION("IFERROR(REGEXEXTRACT(A10,""\| (.+)$""),"""") "),"1L") -> 1L | C10: 288 | D10: 24 | E10: 1 | F10: 4 | G10: =IF(OR(E10="",F10=""),"",E10*F10) -> 4 | H10: 자동 | J10: 엔진오일 | K10: =IF(OR(E10="",F10=""),"",(E10*F10)/7.5) -> 0.53333333 | L10: 정화순, 윤상모, 김세중 | O10: =IF(OR(M10="",N10=""),"",_xlfn.CEILING.MATH((N10-M10-(MEDIAN(N10,"13:00","12:00")-MEDIAN(M10,"13:00","12:00"))-(MEDIAN(N10,"16:30","16:00")-MEDIAN(M10,"16:30","16:00"))),"0:30")*24)
B11: =IFERROR(__xludf.DUMMYFUNCTION("IFERROR(REGEXEXTRACT(A11,""\| (.+)$""),"""") "),"") | G11: =IF(OR(E11="",F11=""),"",E11*F11) | K11: =IF(OR(E11="",F11=""),"",(E11*F11)/7.5) | L11: 정화순, 윤상모, 김세중 | O11: =IF(OR(M11="",N11=""),"",_xlfn.CEILING.MATH((N11-M11-(MEDIAN(N11,"13:00","12:00")-MEDIAN(M11,"13:00","12:00"))-(MEDIAN(N11,"16:30","16:00")-MEDIAN(M11,"16:30","16:00"))),"0:30")*24)
B12: =IFERROR(__xludf.DUMMYFUNCTION("IFERROR(REGEXEXTRACT(A12,""\| (.+)$""),"""") "),"") | G12: =IF(OR(E12="",F12=""),"",E12*F12) | K12: =IF(OR(E12="",F12=""),"",(E12*F12)/7.5) | O12: =IF(OR(M12="",N12=""),"",_xlfn.CEILING.MATH((N12-M12-(MEDIAN(N12,"13:00","12:00")-MEDIAN(M12,"13:00","12:00"))-(MEDIAN(N12,"16:30","16:00")-MEDIAN(M12,"16:30","16:00"))),"0:30")*24)
B13: =IFERROR(__xludf.DUMMYFUNCTION("IFERROR(REGEXEXTRACT(A13,""\| (.+)$""),"""") "),"") | G13: =IF(OR(E13="",F13=""),"",E13*F13) | K13: =IF(OR(E13="",F13=""),"",(E13*F13)/7.5) | O13: =IF(OR(M13="",N13=""),"",_xlfn.CEILING.MATH((N13-M13-(MEDIAN(N13,"13:00","12:00")-MEDIAN(M13,"13:00","12:00"))-(MEDIAN(N13,"16:30","16:00")-MEDIAN(M13,"16:30","16:00"))),"0:30")*24)
B14: =IFERROR(__xludf.DUMMYFUNCTION("IFERROR(REGEXEXTRACT(A14,""\| (.+)$""),"""") "),"") | G14: =IF(OR(E14="",F14=""),"",E14*F14) | K14: =IF(OR(E14="",F14=""),"",(E14*F14)/7.5) | O14: =IF(OR(M14="",N14=""),"",_xlfn.CEILING.MATH((N14-M14-(MEDIAN(N14,"13:00","12:00")-MEDIAN(M14,"13:00","12:00"))-(MEDIAN(N14,"16:30","16:00")-MEDIAN(M14,"16:30","16:00"))),"0:30")*24)
B15: =IFERROR(__xludf.DUMMYFUNCTION("IFERROR(REGEXEXTRACT(A15,""\| (.+)$""),"""") "),"") | G15: =IF(OR(E15="",F15=""),"",E15*F15) | K15: =IF(OR(E15="",F15=""),"",(E15*F15)/7.5) | O15: =IF(OR(M15="",N15=""),"",_xlfn.CEILING.MATH((N15-M15-(MEDIAN(N15,"13:00","12:00")-MEDIAN(M15,"13:00","12:00"))-(MEDIAN(N15,"16:30","16:00")-MEDIAN(M15,"16:30","16:00"))),"0:30")*24)
B16: =IFERROR(__xludf.DUMMYFUNCTION("IFERROR(REGEXEXTRACT(A16,""\| (.+)$""),"""") "),"") | G16: =IF(OR(E16="",F16=""),"",E16*F16) | K16: =IF(OR(E16="",F16=""),"",(E16*F16)/7.5) | O16: =IF(OR(M16="",N16=""),"",_xlfn.CEILING.MATH((N16-M16-(MEDIAN(N16,"13:00","12:00")-MEDIAN(M16,"13:00","12:00"))-(MEDIAN(N16,"16:30","16:00")-MEDIAN(M16,"16:30","16:00"))),"0:30")*24)
B17: =IFERROR(__xludf.DUMMYFUNCTION("IFERROR(REGEXEXTRACT(A17,""\| (.+)$""),"""") "),"") | G17: =IF(OR(E17="",F17=""),"",E17*F17) | K17: =IF(OR(E17="",F17=""),"",(E17*F17)/7.5)
A18: 총수량 | C18: =SUM(C8:C17) -> 1260 | D18: =SUM(D8:D17) -> 105 | E18: =SUM(E8:E17) -> 5 | F18: =IFERROR(G18/E18, 0) -> 3.2 | G18: =SUM(G8:G17) -> 16 | K18: =SUM(K8:K14) -> 2.1333333
A20: ■ 라벨부착작업
A21: 품명 | B21: 용량/규격 | C21: 수량 | D21: 박스 | E21: 작업시간 | F21: 투입인원수 | G21: 총작업시간 | H21: LINE/구분 | I21: 비고(LOT/NO) | J21: 카테고리 | K21: 작업공수 | M21: 시작 | N21: 끝 | O21: 작업시간
A22: DA020669 / 프로텍 브레이크액 DOT-4+ LV 1L 라벨 | 81*111 | B22: =IFERROR(__xludf.DUMMYFUNCTION("IFERROR(REGEXEXTRACT(A22,""\| (.+)$""),"""") "),"81*111") -> 81*111 | C22: 154 | E22: 0.5 | F22: 3 | G22: =IF(OR(E22="",F22=""),"",E22*F22) -> 1.5 | H22: 자동B | J22: 브레이크액 | K22: =IF(OR(E22="",F22=""),"",(E22*F22)/7.5) -> 0.2 | L22: 정화순, 윤상모, 김백철, 김세중 | O22: =IF(OR(M22="",N22=""),"",_xlfn.CEILING.MATH((N22-M22-(MEDIAN(N22,"13:00","12:00")-MEDIAN(M22,"13:00","12:00"))-(MEDIAN(N22,"16:30","16:00")-MEDIAN(M22,"16:30","16:00"))),"0:30")*24)
A23: DA020664 / 프로텍 브레이크액 DOT-4+ 1L 라벨 | 81*111 | B23: =IFERROR(__xludf.DUMMYFUNCTION("IFERROR(REGEXEXTRACT(A23,""\| (.+)$""),"""") "),"81*111") -> 81*111 | C23: 1394 | E23: 1.3 | F23: 3 | G23: =IF(OR(E23="",F23=""),"",E23*F23) -> 3.9 | H23: 자동B | J23: 브레이크액 | K23: =IF(OR(E23="",F23=""),"",(E23*F23)/7.5) -> 0.52 | O23: =IF(OR(M23="",N23=""),"",_xlfn.CEILING.MATH((N23-M23-(MEDIAN(N23,"13:00","12:00")-MEDIAN(M23,"13:00","12:00"))-(MEDIAN(N23,"16:30","16:00")-MEDIAN(M23,"16:30","16:00"))),"0:30")*24)
A24: DO020100 / 썸오일 4T 100% 합성엔진오일 5W-40 1L 라벨 | 81*111 | B24: =IFERROR(__xludf.DUMMYFUNCTION("IFERROR(REGEXEXTRACT(A24,""\| (.+)$""),"""") "),"81*111") -> 81*111 | C24: 520 | E24: 1 | F24: 3 | G24: =IF(OR(E24="",F24=""),"",E24*F24) -> 3 | H24: 자동B | J24: 엔진오일 | K24: =IF(OR(E24="",F24=""),"",(E24*F24)/7.5) -> 0.4 | O24: =IF(OR(M24="",N24=""),"",_xlfn.CEILING.MATH((N24-M24-(MEDIAN(N24,"13:00","12:00")-MEDIAN(M24,"13:00","12:00"))-(MEDIAN(N24,"16:30","16:00")-MEDIAN(M24,"16:30","16:00"))),"0:30")*24)
B25: =IFERROR(__xludf.DUMMYFUNCTION("IFERROR(REGEXEXTRACT(A25,""\| (.+)$""),"""") "),"") | G25: =IF(OR(E25="",F25=""),"",E25*F25) | K25: =IF(OR(E25="",F25=""),"",(E25*F25)/7.5) | O25: =IF(OR(M25="",N25=""),"",_xlfn.CEILING.MATH((N25-M25-(MEDIAN(N25,"13:00","12:00")-MEDIAN(M25,"13:00","12:00"))-(MEDIAN(N25,"16:30","16:00")-MEDIAN(M25,"16:30","16:00"))),"0:30")*24)
B26: =IFERROR(__xludf.DUMMYFUNCTION("IFERROR(REGEXEXTRACT(A26,""\| (.+)$""),"""") "),"") | G26: =IF(OR(E26="",F26=""),"",E26*F26) | K26: =IF(OR(E26="",F26=""),"",(E26*F26)/7.5) | O26: =IF(OR(M26="",N26=""),"",_xlfn.CEILING.MATH((N26-M26-(MEDIAN(N26,"13:00","12:00")-MEDIAN(M26,"13:00","12:00"))-(MEDIAN(N26,"16:30","16:00")-MEDIAN(M26,"16:30","16:00"))),"0:30")*24)
A27: 총수량 | C27: =SUM(C22:C26) -> 2068 | D27: =SUM(D22:D26) -> 0 | E27: =SUM(E22:E26) -> 2.8 | F27: =IFERROR(G27/E27, 0) -> 3 | G27: =SUM(G22:G26) -> 8.4 | K27: =SUM(K22:K26) -> 1.12
A29: ■ 원액생산작업
A30: 품명 | B30: 용량/규격 | C30: 수량 | D30: 포장 | E30: 작업시간 | F30: 투입인원수 | G30: 총작업시간 | H30: LINE/구분 | I30: 비고(LOT/NO) | J30: 카테고리 | K30: 작업공수
A31: 5AJ40009 / 엔진 세척제 (크린텍)-솔벤트 | B31: L | C31: 1000 | D31: TOTE | E31: 1 | F31: 1 | G31: =IF(OR(E31="",F31=""),"",E31*F31) -> 1 | H31: BT-2 | I31: G260918-021 | J31: 엔진세척제 | K31: =IF(OR(E31="",F31=""),"",(E31*F31)/7.5) -> 0.13333333 | L31: 윤경용
A32: 5AA40027 / SUMOIL 5W40 4T | B32: L | C32: 800 | D32: TOTE | E32: 2 | F32: 2 | G32: =IF(OR(E32="",F32=""),"",E32*F32) -> 4 | H32: BT-2 | I32: G260918-022 | J32: 엔진오일 | K32: =IF(OR(E32="",F32=""),"",(E32*F32)/7.5) -> 0.53333333
A33: 5AA40024 / SUMOIL 0W20 | B33: L | C33: 1000 | D33: TOTE | E33: 1 | F33: 2 | G33: =IF(OR(E33="",F33=""),"",E33*F33) -> 2 | H33: BT-2 | I33: G260918-023 | J33: 엔진오일 | K33: =IF(OR(E33="",F33=""),"",(E33*F33)/7.5) -> 0.26666667
A34: 5AA40012 / MOTOR 2T SAE20 | B34: L | C34: 1000 | D34: TOTE | E34: 2 | F34: 2 | G34: =IF(OR(E34="",F34=""),"",E34*F34) -> 4 | H34: BT-2 | I34: G260918-024 | J34: 엔진오일 | K34: =IF(OR(E34="",F34=""),"",(E34*F34)/7.5) -> 0.53333333
G35: =IF(OR(E35="",F35=""),"",E35*F35) | K35: =IF(OR(E35="",F35=""),"",(E35*F35)/7.5)
A36: 총수량 | C36: =SUM(C31:C35) -> 3800 | E36: =SUM(E28:E35) -> 6 | F36: =IFERROR(G36/E36, 0) -> 3.2333333 | G36: =SUM(G26:G35) -> 19.4 | K36: =SUM(K31:K35) -> 1.4666667
A38: ■ 출고내역
A39: 품명 | B39: 용량/규격 | C39: 수량 | D39: 박스 | E39: 거래처 | G39: 확인자 | H39: 운송 | I39: 비고
B40: =IFERROR(__xludf.DUMMYFUNCTION("IFERROR(REGEXEXTRACT(A40,""\| (.+)$""),"""") "),"")
B41: =IFERROR(__xludf.DUMMYFUNCTION("IFERROR(REGEXEXTRACT(A41,""\| (.+)$""),"""") "),"")
B42: =IFERROR(__xludf.DUMMYFUNCTION("IFERROR(REGEXEXTRACT(A42,""\| (.+)$""),"""") "),"")
B43: =IFERROR(__xludf.DUMMYFUNCTION("IFERROR(REGEXEXTRACT(A43,""\| (.+)$""),"""") "),"")
B47: =IFERROR(__xludf.DUMMYFUNCTION("IFERROR(REGEXEXTRACT(A47,""\| (.+)$""),"""") "),"")
A48: 총수량 | C48: =SUM(C40:C47) -> 0
...

Sheet 0917
I1: 담당 | J1: 검토 | K1: 확인
A2: (김포)생산공급망 업무일지 | I2: 최용화 | J2: 윤경용 | N2: 초록색상 지우기와 기재 금지
A4: 날짜 | B4: 46282
A6: ■ 제품포장작업
A7: 품명 | B7: 용량/규격 | C7: 수량 | D7: 박스 | E7: 작업시간 | F7: 투입인원수 | G7: 총작업시간 | H7: LINE/구분 | I7: 비고(LOT/NO) | J7: 카테고리 | K7: 작업공수 | L7: 작업자 | M7: 시작 | N7: 끝 | O7: 작업시간
A8: 1AA40013 / 미라텍 플러스 100% 합성엔진오일 5W30 | 1L | B8: =IFERROR(__xludf.DUMMYFUNCTION("IFERROR(REGEXEXTRACT(A8,""\| (.+)$""),"""") "),"1L") -> 1L | C8: 720 | D8: 60 | E8: 1.5 | F8: 3 | G8: =IF(OR(E8="",F8=""),"",E8*F8) -> 4.5 | H8: 자동 | I8: 260916 | J8: 엔진오일 | K8: =IF(OR(E8="",F8=""),"",(E8*F8)/7.5) -> 0.6 | L8: 정화순, 윤상모, 김백철, 김세중 | O8: =IF(OR(M8="",N8=""),"",_xlfn.CEILING.MATH((N8-M8-(MEDIAN(N8,"13:00","12:00")-MEDIAN(M8,"13:00","12:00"))-(MEDIAN(N8,"16:30","16:00")-MEDIAN(M8,"16:30","16:00"))),"0:30")*24)
A9: 2AA40017 / 넘버원 100%합성엔진오일 5W30 | 1L | B9: =IFERROR(__xludf.DUMMYFUNCTION("IFERROR(REGEXEXTRACT(A9,""\| (.+)$""),"""") "),"1L") -> 1L | C9: 720 | D9: 60 | E9: 2 | F9: 3 | G9: =IF(OR(E9="",F9=""),"",E9*F9) -> 6 | H9: 자동 | I9: 260917 | J9: 엔진오일 | K9: =IF(OR(E9="",F9=""),"",(E9*F9)/7.5) -> 0.8 | L9: 정화순, 윤상모, 김세중 | O9: =IF(OR(M9="",N9=""),"",_xlfn.CEILING.MATH((N9-M9-(MEDIAN(N9,"13:00","12:00")-MEDIAN(M9,"13:00","12:00"))-(MEDIAN(N9,"16:30","16:00")-MEDIAN(M9,"16:30","16:00"))),"0:30")*24)
A10: 2AA40003 / GT Formula 엔진오일 PAO 5W30 | 1L | B10: =IFERROR(__xludf.DUMMYFUNCTION("IFERROR(REGEXEXTRACT(A10,""\| (.+)$""),"""") "),"1L") -> 1L | C10: 876 | D10: 73 | E10: 3 | F10: 3 | G10: =IF(OR(E10="",F10=""),"",E10*F10) -> 9 | H10: 자동 | J10: 엔진오일 | K10: =IF(OR(E10="",F10=""),"",(E10*F10)/7.5) -> 1.2 | L10: 정화순, 윤상모, 김세중 | O10: =IF(OR(M10="",N10=""),"",_xlfn.CEILING.MATH((N10-M10-(MEDIAN(N10,"13:00","12:00")-MEDIAN(M10,"13:00","12:00"))-(MEDIAN(N10,"16:30","16:00")-MEDIAN(M10,"16:30","16:00"))),"0:30")*24)
B11: =IFERROR(__xludf.DUMMYFUNCTION("IFERROR(REGEXEXTRACT(A11,""\| (.+)$""),"""") "),"") | G11: =IF(OR(E11="",F11=""),"",E11*F11) | K11: =IF(OR(E11="",F11=""),"",(E11*F11)/7.5) | L11: 정화순, 윤상모, 김세중 | O11: =IF(OR(M11="",N11=""),"",_xlfn.CEILING.MATH((N11-M11-(MEDIAN(N11,"13:00","12:00")-MEDIAN(M11,"13:00","12:00"))-(MEDIAN(N11,"16:30","16:00")-MEDIAN(M11,"16:30","16:00"))),"0:30")*24)
B12: =IFERROR(__xludf.DUMMYFUNCTION("IFERROR(REGEXEXTRACT(A12,""\| (.+)$""),"""") "),"") | G12: =IF(OR(E12="",F12=""),"",E12*F12) | K12: =IF(OR(E12="",F12=""),"",(E12*F12)/7.5) | O12: =IF(OR(M12="",N12=""),"",_xlfn.CEILING.MATH((N12-M12-(MEDIAN(N12,"13:00","12:00")-MEDIAN(M12,"13:00","12:00"))-(MEDIAN(N12,"16:30","16:00")-MEDIAN(M12,"16:30","16:00"))),"0:30")*24)
B13: =IFERROR(__xludf.DUMMYFUNCTION("IFERROR(REGEXEXTRACT(A13,""\| (.+)$""),"""") "),"") | G13: =IF(OR(E13="",F13=""),"",E13*F13) | K13: =IF(OR(E13="",F13=""),"",(E13*F13)/7.5) | O13: =IF(OR(M13="",N13=""),"",_xlfn.CEILING.MATH((N13-M13-(MEDIAN(N13,"13:00","12:00")-MEDIAN(M13,"13:00","12:00"))-(MEDIAN(N13,"16:30","16:00")-MEDIAN(M13,"16:30","16:00"))),"0:30")*24)
B14: =IFERROR(__xludf.DUMMYFUNCTION("IFERROR(REGEXEXTRACT(A14,""\| (.+)$""),"""") "),"") | G14: =IF(OR(E14="",F14=""),"",E14*F14) | K14: =IF(OR(E14="",F14=""),"",(E14*F14)/7.5) | O14: =IF(OR(M14="",N14=""),"",_xlfn.CEILING.MATH((N14-M14-(MEDIAN(N14,"13:00","12:00")-MEDIAN(M14,"13:00","12:00"))-(MEDIAN(N14,"16:30","16:00")-MEDIAN(M14,"16:30","16:00"))),"0:30")*24)
B15: =IFERROR(__xludf.DUMMYFUNCTION("IFERROR(REGEXEXTRACT(A15,""\| (.+)$""),"""") "),"") | G15: =IF(OR(E15="",F15=""),"",E15*F15) | K15: =IF(OR(E15="",F15=""),"",(E15*F15)/7.5) | O15: =IF(OR(M15="",N15=""),"",_xlfn.CEILING.MATH((N15-M15-(MEDIAN(N15,"13:00","12:00")-MEDIAN(M15,"13:00","12:00"))-(MEDIAN(N15,"16:30","16:00")-MEDIAN(M15,"16:30","16:00"))),"0:30")*24)
B16: =IFERROR(__xludf.DUMMYFUNCTION("IFERROR(REGEXEXTRACT(A16,""\| (.+)$""),"""") "),"") | G16: =IF(OR(E16="",F16=""),"",E16*F16) | K16: =IF(OR(E16="",F16=""),"",(E16*F16)/7.5) | O16: =IF(OR(M16="",N16=""),"",_xlfn.CEILING.MATH((N16-M16-(MEDIAN(N16,"13:00","12:00")-MEDIAN(M16,"13:00","12:00"))-(MEDIAN(N16,"16:30","16:00")-MEDIAN(M16,"16:30","16:00"))),"0:30")*24)
B17: =IFERROR(__xludf.DUMMYFUNCTION("IFERROR(REGEXEXTRACT(A17,""\| (.+)$""),"""") "),"") | G17: =IF(OR(E17="",F17=""),"",E17*F17) | K17: =IF(OR(E17="",F17=""),"",(E17*F17)/7.5)
A18: 총수량 | C18: =SUM(C8:C17) -> 2316 | D18: =SUM(D8:D17) -> 193 | E18: =SUM(E8:E17) -> 6.5 | F18: =IFERROR(G18/E18, 0) -> 3 | G18: =SUM(G8:G17) -> 19.5 | K18: =SUM(K8:K14) -> 2.6
A20: ■ 라벨부착작업
A21: 품명 | B21: 용량/규격 | C21: 수량 | D21: 박스 | E21: 작업시간 | F21: 투입인원수 | G21: 총작업시간 | H21: LINE/구분 | I21: 비고(LOT/NO) | J21: 카테고리 | K21: 작업공수 | M21: 시작 | N21: 끝 | O21: 작업시간
A22: OO020695 / 넘버원 5w30 가솔린 디젤 합성엔진오일 1L 라벨 | 90*140 | B22: =IFERROR(__xludf.DUMMYFUNCTION("IFERROR(REGEXEXTRACT(A22,""\| (.+)$""),"""") "),"90*140") -> 90*140 | C22: 60 | E22: 0.5 | F22: 3 | G22: =IF(OR(E22="",F22=""),"",E22*F22) -> 1.5 | H22: 수동 | J22: 엔진오일 | K22: =IF(OR(E22="",F22=""),"",(E22*F22)/7.5) -> 0.2 | L22: 정화순, 윤상모, 김백철, 김세중 | O22: =IF(OR(M22="",N22=""),"",_xlfn.CEILING.MATH((N22-M22-(MEDIAN(N22,"13:00","12:00")-MEDIAN(M22,"13:00","12:00"))-(MEDIAN(N22,"16:30","16:00")-MEDIAN(M22,"16:30","16:00"))),"0:30")*24)
B23: =IFERROR(__xludf.DUMMYFUNCTION("IFERROR(REGEXEXTRACT(A23,""\| (.+)$""),"""") "),"") | G23: =IF(OR(E23="",F23=""),"",E23*F23) | K23: =IF(OR(E23="",F23=""),"",(E23*F23)/7.5) | O23: =IF(OR(M23="",N23=""),"",_xlfn.CEILING.MATH((N23-M23-(MEDIAN(N23,"13:00","12:00")-MEDIAN(M23,"13:00","12:00"))-(MEDIAN(N23,"16:30","16:00")-MEDIAN(M23,"16:30","16:00"))),"0:30")*24)
B24: =IFERROR(__xludf.DUMMYFUNCTION("IFERROR(REGEXEXTRACT(A24,""\| (.+)$""),"""") "),"") | G24: =IF(OR(E24="",F24=""),"",E24*F24) | K24: =IF(OR(E24="",F24=""),"",(E24*F24)/7.5) | O24: =IF(OR(M24="",N24=""),"",_xlfn.CEILING.MATH((N24-M24-(MEDIAN(N24,"13:00","12:00")-MEDIAN(M24,"13:00","12:00"))-(MEDIAN(N24,"16:30","16:00")-MEDIAN(M24,"16:30","16:00"))),"0:30")*24)
B25: =IFERROR(__xludf.DUMMYFUNCTION("IFERROR(REGEXEXTRACT(A25,""\| (.+)$""),"""") "),"") | G25: =IF(OR(E25="",F25=""),"",E25*F25) | K25: =IF(OR(E25="",F25=""),"",(E25*F25)/7.5) | O25: =IF(OR(M25="",N25=""),"",_xlfn.CEILING.MATH((N25-M25-(MEDIAN(N25,"13:00","12:00")-MEDIAN(M25,"13:00","12:00"))-(MEDIAN(N25,"16:30","16:00")-MEDIAN(M25,"16:30","16:00"))),"0:30")*24)
B26: =IFERROR(__xludf.DUMMYFUNCTION("IFERROR(REGEXEXTRACT(A26,""\| (.+)$""),"""") "),"") | G26: =IF(OR(E26="",F26=""),"",E26*F26) | K26: =IF(OR(E26="",F26=""),"",(E26*F26)/7.5) | O26: =IF(OR(M26="",N26=""),"",_xlfn.CEILING.MATH((N26-M26-(MEDIAN(N26,"13:00","12:00")-MEDIAN(M26,"13:00","12:00"))-(MEDIAN(N26,"16:30","16:00")-MEDIAN(M26,"16:30","16:00"))),"0:30")*24)
A27: 총수량 | C27: =SUM(C22:C26) -> 60 | D27: =SUM(D22:D26) -> 0 | E27: =SUM(E22:E26) -> 0.5 | F27: =IFERROR(G27/E27, 0) -> 3 | G27: =SUM(G22:G26) -> 1.5 | K27: =SUM(K22:K26) -> 0.2
A29: ■ 원액생산작업
A30: 품명 | B30: 용량/규격 | C30: 수량 | D30: 포장 | E30: 작업시간 | F30: 투입인원수 | G30: 총작업시간 | H30: LINE/구분 | I30: 비고(LOT/NO) | J30: 카테고리 | K30: 작업공수
A31: 5AA40008 / ODM 5W30 | B31: L | C31: 1694 | D31: TOTE | E31: 3 | F31: 1 | G31: =IF(OR(E31="",F31=""),"",E31*F31) -> 3 | H31: BT-2 | I31: G260917-021 | J31: 엔진오일 | K31: =IF(OR(E31="",F31=""),"",(E31*F31)/7.5) -> 0.4 | L31: 윤경용
G32: =IF(OR(E32="",F32=""),"",E32*F32) | K32: =IF(OR(E32="",F32=""),"",(E32*F32)/7.5)
G33: =IF(OR(E33="",F33=""),"",E33*F33) | K33: =IF(OR(E33="",F33=""),"",(E33*F33)/7.5)
G34: =IF(OR(E34="",F34=""),"",E34*F34) | K34: =IF(OR(E34="",F34=""),"",(E34*F34)/7.5)
G35: =IF(OR(E35="",F35=""),"",E35*F35) | K35: =IF(OR(E35="",F35=""),"",(E35*F35)/7.5)
A36: 총수량 | C36: =SUM(C31:C35) -> 1694 | E36: =SUM(E28:E35) -> 3 | F36: =IFERROR(G36/E36, 0) -> 1.5 | G36: =SUM(G26:G35) -> 4.5 | K36: =SUM(K31:K35) -> 0.4
A38: ■ 출고내역
A39: 품명 | B39: 용량/규격 | C39: 수량 | D39: 박스 | E39: 거래처 | G39: 확인자 | H39: 운송 | I39: 비고
A40: 1AA40005 / 썸오일 100% 합성엔진오일 5W30 | 1L | B40: =IFERROR(__xludf.DUMMYFUNCTION("IFERROR(REGEXEXTRACT(A40,""\| (.+)$""),"""") "),"1L") -> 1L | C40: 720 | D40: 60 | E40: 현대카프라자 | G40: 윤경용 | H40: 택배
B41: =IFERROR(__xludf.DUMMYFUNCTION("IFERROR(REGEXEXTRACT(A41,""\| (.+)$""),"""") "),"")
B42: =IFERROR(__xludf.DUMMYFUNCTION("IFERROR(REGEXEXTRACT(A42,""\| (.+)$""),"""") "),"")
B43: =IFERROR(__xludf.DUMMYFUNCTION("IFERROR(REGEXEXTRACT(A43,""\| (.+)$""),"""") "),"")
B47: =IFERROR(__xludf.DUMMYFUNCTION("IFERROR(REGEXEXTRACT(A47,""\| (.+)$""),"""") "),"")
A48: 총수량 | C48: =SUM(C40:C47) -> 720
...

Sheet 0916
I1: 담당 | J1: 검토 | K1: 확인
A2: (김포)생산공급망 업무일지 | I2: 최용화 | J2: 윤경용 | N2: 초록색상 지우기와 기재 금지
A4: 날짜 | B4: 46281
A6: ■ 제품포장작업
A7: 품명 | B7: 용량/규격 | C7: 수량 | D7: 박스 | E7: 작업시간 | F7: 투입인원수 | G7: 총작업시간 | H7: LINE/구분 | I7: 비고(LOT/NO) | J7: 카테고리 | K7: 작업공수 | L7: 작업자 | M7: 시작 | N7: 끝 | O7: 작업시간
A8: 2AA40003 / GT Formula 엔진오일 PAO 5W30 | 1L | B8: =IFERROR(__xludf.DUMMYFUNCTION("IFERROR(REGEXEXTRACT(A8,""\| (.+)$""),"""") "),"1L") -> 1L | C8: 204 | D8: 17 | E8: 1 | F8: 4 | G8: =IF(OR(E8="",F8=""),"",E8*F8) -> 4 | H8: 자동 | J8: 엔진오일 | K8: =IF(OR(E8="",F8=""),"",(E8*F8)/7.5) -> 0.53333333 | L8: 정화순, 윤상모, 김백철, 김세중 | O8: =IF(OR(M8="",N8=""),"",_xlfn.CEILING.MATH((N8-M8-(MEDIAN(N8,"13:00","12:00")-MEDIAN(M8,"13:00","12:00"))-(MEDIAN(N8,"16:30","16:00")-MEDIAN(M8,"16:30","16:00"))),"0:30")*24)
A9: 1AA40015 / 미라텍탑 PAO 100% 합성엔진오일 5W30 | 1L | B9: =IFERROR(__xludf.DUMMYFUNCTION("IFERROR(REGEXEXTRACT(A9,""\| (.+)$""),"""") "),"1L") -> 1L | C9: 720 | D9: 60 | E9: 2.5 | F9: 3 | G9: =IF(OR(E9="",F9=""),"",E9*F9) -> 7.5 | H9: 자동 | I9: 260916 | J9: 엔진오일 | K9: =IF(OR(E9="",F9=""),"",(E9*F9)/7.5) -> 1 | L9: 정화순, 윤상모, 김세중 | O9: =IF(OR(M9="",N9=""),"",_xlfn.CEILING.MATH((N9-M9-(MEDIAN(N9,"13:00","12:00")-MEDIAN(M9,"13:00","12:00"))-(MEDIAN(N9,"16:30","16:00")-MEDIAN(M9,"16:30","16:00"))),"0:30")*24)
A10: 1AA40013 / 미라텍 플러스 100% 합성엔진오일 5W30 | 1L | B10: =IFERROR(__xludf.DUMMYFUNCTION("IFERROR(REGEXEXTRACT(A10,""\| (.+)$""),"""") "),"1L") -> 1L | C10: 720 | D10: 60 | E10: 1.5 | F10: 3 | G10: =IF(OR(E10="",F10=""),"",E10*F10) -> 4.5 | H10: 자동 | I10: 260916 | J10: 엔진오일 | K10: =IF(OR(E10="",F10=""),"",(E10*F10)/7.5) -> 0.6 | L10: 정화순, 윤상모, 김세중 | O10: =IF(OR(M10="",N10=""),"",_xlfn.CEILING.MATH((N10-M10-(MEDIAN(N10,"13:00","12:00")-MEDIAN(M10,"13:00","12:00"))-(MEDIAN(N10,"16:30","16:00")-MEDIAN(M10,"16:30","16:00"))),"0:30")*24)
A11: 2AA40003 / GT Formula 엔진오일 PAO 5W30 | 1L | B11: =IFERROR(__xludf.DUMMYFUNCTION("IFERROR(REGEXEXTRACT(A11,""\| (.+)$""),"""") "),"1L") -> 1L | C11: 648 | D11: 54 | E11: 2 | F11: 3 | G11: =IF(OR(E11="",F11=""),"",E11*F11) -> 6 | H11: 자동 | J11: 엔진오일 | K11: =IF(OR(E11="",F11=""),"",(E11*F11)/7.5) -> 0.8 | L11: 정화순, 윤상모, 김세중 | O11: =IF(OR(M11="",N11=""),"",_xlfn.CEILING.MATH((N11-M11-(MEDIAN(N11,"13:00","12:00")-MEDIAN(M11,"13:00","12:00"))-(MEDIAN(N11,"16:30","16:00")-MEDIAN(M11,"16:30","16:00"))),"0:30")*24)
B12: =IFERROR(__xludf.DUMMYFUNCTION("IFERROR(REGEXEXTRACT(A12,""\| (.+)$""),"""") "),"") | G12: =IF(OR(E12="",F12=""),"",E12*F12) | K12: =IF(OR(E12="",F12=""),"",(E12*F12)/7.5) | O12: =IF(OR(M12="",N12=""),"",_xlfn.CEILING.MATH((N12-M12-(MEDIAN(N12,"13:00","12:00")-MEDIAN(M12,"13:00","12:00"))-(MEDIAN(N12,"16:30","16:00")-MEDIAN(M12,"16:30","16:00"))),"0:30")*24)
B13: =IFERROR(__xludf.DUMMYFUNCTION("IFERROR(REGEXEXTRACT(A13,""\| (.+)$""),"""") "),"") | G13: =IF(OR(E13="",F13=""),"",E13*F13) | K13: =IF(OR(E13="",F13=""),"",(E13*F13)/7.5) | O13: =IF(OR(M13="",N13=""),"",_xlfn.CEILING.MATH((N13-M13-(MEDIAN(N13,"13:00","12:00")-MEDIAN(M13,"13:00","12:00"))-(MEDIAN(N13,"16:30","16:00")-MEDIAN(M13,"16:30","16:00"))),"0:30")*24)
B14: =IFERROR(__xludf.DUMMYFUNCTION("IFERROR(REGEXEXTRACT(A14,""\| (.+)$""),"""") "),"") | G14: =IF(OR(E14="",F14=""),"",E14*F14) | K14: =IF(OR(E14="",F14=""),"",(E14*F14)/7.5) | O14: =IF(OR(M14="",N14=""),"",_xlfn.CEILING.MATH((N14-M14-(MEDIAN(N14,"13:00","12:00")-MEDIAN(M14,"13:00","12:00"))-(MEDIAN(N14,"16:30","16:00")-MEDIAN(M14,"16:30","16:00"))),"0:30")*24)
B15: =IFERROR(__xludf.DUMMYFUNCTION("IFERROR(REGEXEXTRACT(A15,""\| (.+)$""),"""") "),"") | G15: =IF(OR(E15="",F15=""),"",E15*F15) | K15: =IF(OR(E15="",F15=""),"",(E15*F15)/7.5) | O15: =IF(OR(M15="",N15=""),"",_xlfn.CEILING.MATH((N15-M15-(MEDIAN(N15,"13:00","12:00")-MEDIAN(M15,"13:00","12:00"))-(MEDIAN(N15,"16:30","16:00")-MEDIAN(M15,"16:30","16:00"))),"0:30")*24)
B16: =IFERROR(__xludf.DUMMYFUNCTION("IFERROR(REGEXEXTRACT(A16,""\| (.+)$""),"""") "),"") | G16: =IF(OR(E16="",F16=""),"",E16*F16) | K16: =IF(OR(E16="",F16=""),"",(E16*F16)/7.5) | O16: =IF(OR(M16="",N16=""),"",_xlfn.CEILING.MATH((N16-M16-(MEDIAN(N16,"13:00","12:00")-MEDIAN(M16,"13:00","12:00"))-(MEDIAN(N16,"16:30","16:00")-MEDIAN(M16,"16:30","16:00"))),"0:30")*24)
B17: =IFERROR(__xludf.DUMMYFUNCTION("IFERROR(REGEXEXTRACT(A17,""\| (.+)$""),"""") "),"") | G17: =IF(OR(E17="",F17=""),"",E17*F17) | K17: =IF(OR(E17="",F17=""),"",(E17*F17)/7.5)
A18: 총수량 | C18: =SUM(C8:C17) -> 2292 | D18: =SUM(D8:D17) -> 191 | E18: =SUM(E8:E17) -> 7 | F18: =IFERROR(G18/E18, 0) -> 3.1428571 | G18: =SUM(G8:G17) -> 22 | K18: =SUM(K8:K14) -> 2.9333333
A20: ■ 라벨부착작업
A21: 품명 | B21: 용량/규격 | C21: 수량 | D21: 박스 | E21: 작업시간 | F21: 투입인원수 | G21: 총작업시간 | H21: LINE/구분 | I21: 비고(LOT/NO) | J21: 카테고리 | K21: 작업공수 | M21: 시작 | N21: 끝 | O21: 작업시간
A22: 2AA20004 / GT 엔진오일 PAO 5W-30 1L 라벨 | 92*110 | B22: =IFERROR(__xludf.DUMMYFUNCTION("IFERROR(REGEXEXTRACT(A22,""\| (.+)$""),"""") "),"92*110") -> 92*110 | C22: 120 | E22: 0.5 | F22: 4 | G22: =IF(OR(E22="",F22=""),"",E22*F22) -> 2 | H22: 수동 | J22: 엔진오일 | K22: =IF(OR(E22="",F22=""),"",(E22*F22)/7.5) -> 0.26666667 | L22: 정화순, 윤상모, 김백철, 김세중 | O22: =IF(OR(M22="",N22=""),"",_xlfn.CEILING.MATH((N22-M22-(MEDIAN(N22,"13:00","12:00")-MEDIAN(M22,"13:00","12:00"))-(MEDIAN(N22,"16:30","16:00")-MEDIAN(M22,"16:30","16:00"))),"0:30")*24)
B23: =IFERROR(__xludf.DUMMYFUNCTION("IFERROR(REGEXEXTRACT(A23,""\| (.+)$""),"""") "),"") | G23: =IF(OR(E23="",F23=""),"",E23*F23) | K23: =IF(OR(E23="",F23=""),"",(E23*F23)/7.5) | O23: =IF(OR(M23="",N23=""),"",_xlfn.CEILING.MATH((N23-M23-(MEDIAN(N23,"13:00","12:00")-MEDIAN(M23,"13:00","12:00"))-(MEDIAN(N23,"16:30","16:00")-MEDIAN(M23,"16:30","16:00"))),"0:30")*24)
B24: =IFERROR(__xludf.DUMMYFUNCTION("IFERROR(REGEXEXTRACT(A24,""\| (.+)$""),"""") "),"") | G24: =IF(OR(E24="",F24=""),"",E24*F24) | K24: =IF(OR(E24="",F24=""),"",(E24*F24)/7.5) | O24: =IF(OR(M24="",N24=""),"",_xlfn.CEILING.MATH((N24-M24-(MEDIAN(N24,"13:00","12:00")-MEDIAN(M24,"13:00","12:00"))-(MEDIAN(N24,"16:30","16:00")-MEDIAN(M24,"16:30","16:00"))),"0:30")*24)
B25: =IFERROR(__xludf.DUMMYFUNCTION("IFERROR(REGEXEXTRACT(A25,""\| (.+)$""),"""") "),"") | G25: =IF(OR(E25="",F25=""),"",E25*F25) | K25: =IF(OR(E25="",F25=""),"",(E25*F25)/7.5) | O25: =IF(OR(M25="",N25=""),"",_xlfn.CEILING.MATH((N25-M25-(MEDIAN(N25,"13:00","12:00")-MEDIAN(M25,"13:00","12:00"))-(MEDIAN(N25,"16:30","16:00")-MEDIAN(M25,"16:30","16:00"))),"0:30")*24)
B26: =IFERROR(__xludf.DUMMYFUNCTION("IFERROR(REGEXEXTRACT(A26,""\| (.+)$""),"""") "),"") | G26: =IF(OR(E26="",F26=""),"",E26*F26) | K26: =IF(OR(E26="",F26=""),"",(E26*F26)/7.5) | O26: =IF(OR(M26="",N26=""),"",_xlfn.CEILING.MATH((N26-M26-(MEDIAN(N26,"13:00","12:00")-MEDIAN(M26,"13:00","12:00"))-(MEDIAN(N26,"16:30","16:00")-MEDIAN(M26,"16:30","16:00"))),"0:30")*24)
A27: 총수량 | C27: =SUM(C22:C26) -> 120 | D27: =SUM(D22:D26) -> 0 | E27: =SUM(E22:E26) -> 0.5 | F27: =IFERROR(G27/E27, 0) -> 4 | G27: =SUM(G22:G26) -> 2 | K27: =SUM(K22:K26) -> 0.26666667
A29: ■ 원액생산작업
A30: 품명 | B30: 용량/규격 | C30: 수량 | D30: 포장 | E30: 작업시간 | F30: 투입인원수 | G30: 총작업시간 | H30: LINE/구분 | I30: 비고(LOT/NO) | J30: 카테고리 | K30: 작업공수
A31: 5AJ40015 / 유압작동유 AW32 | B31: L | C31: 3298 | D31: TOTE | E31: 3 | F31: 1 | G31: =IF(OR(E31="",F31=""),"",E31*F31) -> 3 | H31: BT-2 | I31: G260916-021 | J31: 기타 | K31: =IF(OR(E31="",F31=""),"",(E31*F31)/7.5) -> 0.4 | L31: 김백철
A32: 프리미엄 브레이크액 DOT-4+ (시생산용) | B32: L | C32: 600 | D32: DM | E32: 3 | F32: 1 | G32: =IF(OR(E32="",F32=""),"",E32*F32) -> 3 | H32: BT-6 | I32: G260916-061 | J32: 브레이크액 | K32: =IF(OR(E32="",F32=""),"",(E32*F32)/7.5) -> 0.4 | L32: 윤경용
G33: =IF(OR(E33="",F33=""),"",E33*F33) | K33: =IF(OR(E33="",F33=""),"",(E33*F33)/7.5)
G34: =IF(OR(E34="",F34=""),"",E34*F34) | K34: =IF(OR(E34="",F34=""),"",(E34*F34)/7.5)
G35: =IF(OR(E35="",F35=""),"",E35*F35) | K35: =IF(OR(E35="",F35=""),"",(E35*F35)/7.5)
A36: 총수량 | C36: =SUM(C31:C35) -> 3898 | E36: =SUM(E28:E35) -> 6 | F36: =IFERROR(G36/E36, 0) -> 1.3333333 | G36: =SUM(G26:G35) -> 8 | K36: =SUM(K31:K35) -> 0.8
A38: ■ 출고내역
A39: 품명 | B39: 용량/규격 | C39: 수량 | D39: 박스 | E39: 거래처 | G39: 확인자 | H39: 운송 | I39: 비고
A40: 3AA40001 / CTWD 100%합성엔진오일 0W20 | 1L | B40: =IFERROR(__xludf.DUMMYFUNCTION("IFERROR(REGEXEXTRACT(A40,""\| (.+)$""),"""") "),"1L") -> 1L | C40: 2004 | D40: 167 | E40: 베에프코리아 | G40: 윤경용 | H40: 용차 | I40: 운송료:319,000원 VAT포함
A41: 3AA40003 / CTWD 100%합성엔진오일 5W30 | 1L | B41: =IFERROR(__xludf.DUMMYFUNCTION("IFERROR(REGEXEXTRACT(A41,""\| (.+)$""),"""") "),"1L") -> 1L | C41: 2004 | D41: 167 | E41: 베에프코리아 | G41: 윤경용 | H41: 용차
B42: =IFERROR(__xludf.DUMMYFUNCTION("IFERROR(REGEXEXTRACT(A42,""\| (.+)$""),"""") "),"")
B43: =IFERROR(__xludf.DUMMYFUNCTION("IFERROR(REGEXEXTRACT(A43,""\| (.+)$""),"""") "),"")
B47: =IFERROR(__xludf.DUMMYFUNCTION("IFERROR(REGEXEXTRACT(A47,""\| (.+)$""),"""") "),"")
A48: 총수량 | C48: =SUM(C40:C47) -> 4008
...

Sheet 0915
I1: 담당 | J1: 검토 | K1: 확인
A2: (김포)생산공급망 업무일지 | I2: 최용화 | J2: 윤경용 | N2: 초록색상 지우기와 기재 금지
A4: 날짜 | B4: 46280
A6: ■ 제품포장작업
A7: 품명 | B7: 용량/규격 | C7: 수량 | D7: 박스 | E7: 작업시간 | F7: 투입인원수 | G7: 총작업시간 | H7: LINE/구분 | I7: 비고(LOT/NO) | J7: 카테고리 | K7: 작업공수 | L7: 작업자 | M7: 시작 | N7: 끝 | O7: 작업시간
A8: 1AH40002 / 프로텍 프리미엄 브레이크액 DOT-4+ LV | 1L | B8: =IFERROR(__xludf.DUMMYFUNCTION("IFERROR(REGEXEXTRACT(A8,""\| (.+)$""),"""") "),"1L") -> 1L | C8: 792 | D8: 66 | E8: 3 | F8: 2 | G8: =IF(OR(E8="",F8=""),"",E8*F8) -> 6 | H8: 수동3 | I8: 260914 | J8: 브레이크액 | K8: =IF(OR(E8="",F8=""),"",(E8*F8)/7.5) -> 0.8 | L8: 윤상모, 김세중 | O8: =IF(OR(M8="",N8=""),"",_xlfn.CEILING.MATH((N8-M8-(MEDIAN(N8,"13:00","12:00")-MEDIAN(M8,"13:00","12:00"))-(MEDIAN(N8,"16:30","16:00")-MEDIAN(M8,"16:30","16:00"))),"0:30")*24)
A9: 1AH40002 / 프로텍 프리미엄 브레이크액 DOT-4+ LV | 1L | B9: =IFERROR(__xludf.DUMMYFUNCTION("IFERROR(REGEXEXTRACT(A9,""\| (.+)$""),"""") "),"1L") -> 1L | C9: 1440 | D9: 120 | E9: 4.5 | F9: 3 | G9: =IF(OR(E9="",F9=""),"",E9*F9) -> 13.5 | H9: 수동3 | I9: 260914 | J9: 브레이크액 | K9: =IF(OR(E9="",F9=""),"",(E9*F9)/7.5) -> 1.8 | L9: 정화순, 윤상모, 김세중 | O9: =IF(OR(M9="",N9=""),"",_xlfn.CEILING.MATH((N9-M9-(MEDIAN(N9,"13:00","12:00")-MEDIAN(M9,"13:00","12:00"))-(MEDIAN(N9,"16:30","16:00")-MEDIAN(M9,"16:30","16:00"))),"0:30")*24)
B10: =IFERROR(__xludf.DUMMYFUNCTION("IFERROR(REGEXEXTRACT(A10,""\| (.+)$""),"""") "),"") | G10: =IF(OR(E10="",F10=""),"",E10*F10) | K10: =IF(OR(E10="",F10=""),"",(E10*F10)/7.5) | O10: =IF(OR(M10="",N10=""),"",_xlfn.CEILING.MATH((N10-M10-(MEDIAN(N10,"13:00","12:00")-MEDIAN(M10,"13:00","12:00"))-(MEDIAN(N10,"16:30","16:00")-MEDIAN(M10,"16:30","16:00"))),"0:30")*24)
B11: =IFERROR(__xludf.DUMMYFUNCTION("IFERROR(REGEXEXTRACT(A11,""\| (.+)$""),"""") "),"") | G11: =IF(OR(E11="",F11=""),"",E11*F11) | K11: =IF(OR(E11="",F11=""),"",(E11*F11)/7.5) | O11: =IF(OR(M11="",N11=""),"",_xlfn.CEILING.MATH((N11-M11-(MEDIAN(N11,"13:00","12:00")-MEDIAN(M11,"13:00","12:00"))-(MEDIAN(N11,"16:30","16:00")-MEDIAN(M11,"16:30","16:00"))),"0:30")*24)
B12: =IFERROR(__xludf.DUMMYFUNCTION("IFERROR(REGEXEXTRACT(A12,""\| (.+)$""),"""") "),"") | G12: =IF(OR(E12="",F12=""),"",E12*F12) | K12: =IF(OR(E12="",F12=""),"",(E12*F12)/7.5) | O12: =IF(OR(M12="",N12=""),"",_xlfn.CEILING.MATH((N12-M12-(MEDIAN(N12,"13:00","12:00")-MEDIAN(M12,"13:00","12:00"))-(MEDIAN(N12,"16:30","16:00")-MEDIAN(M12,"16:30","16:00"))),"0:30")*24)
B13: =IFERROR(__xludf.DUMMYFUNCTION("IFERROR(REGEXEXTRACT(A13,""\| (.+)$""),"""") "),"") | G13: =IF(OR(E13="",F13=""),"",E13*F13) | K13: =IF(OR(E13="",F13=""),"",(E13*F13)/7.5) | O13: =IF(OR(M13="",N13=""),"",_xlfn.CEILING.MATH((N13-M13-(MEDIAN(N13,"13:00","12:00")-MEDIAN(M13,"13:00","12:00"))-(MEDIAN(N13,"16:30","16:00")-MEDIAN(M13,"16:30","16:00"))),"0:30")*24)
B14: =IFERROR(__xludf.DUMMYFUNCTION("IFERROR(REGEXEXTRACT(A14,""\| (.+)$""),"""") "),"") | G14: =IF(OR(E14="",F14=""),"",E14*F14) | K14: =IF(OR(E14="",F14=""),"",(E14*F14)/7.5) | O14: =IF(OR(M14="",N14=""),"",_xlfn.CEILING.MATH((N14-M14-(MEDIAN(N14,"13:00","12:00")-MEDIAN(M14,"13:00","12:00"))-(MEDIAN(N14,"16:30","16:00")-MEDIAN(M14,"16:30","16:00"))),"0:30")*24)
B15: =IFERROR(__xludf.DUMMYFUNCTION("IFERROR(REGEXEXTRACT(A15,""\| (.+)$""),"""") "),"") | G15: =IF(OR(E15="",F15=""),"",E15*F15) | K15: =IF(OR(E15="",F15=""),"",(E15*F15)/7.5) | O15: =IF(OR(M15="",N15=""),"",_xlfn.CEILING.MATH((N15-M15-(MEDIAN(N15,"13:00","12:00")-MEDIAN(M15,"13:00","12:00"))-(MEDIAN(N15,"16:30","16:00")-MEDIAN(M15,"16:30","16:00"))),"0:30")*24)
B16: =IFERROR(__xludf.DUMMYFUNCTION("IFERROR(REGEXEXTRACT(A16,""\| (.+)$""),"""") "),"") | G16: =IF(OR(E16="",F16=""),"",E16*F16) | K16: =IF(OR(E16="",F16=""),"",(E16*F16)/7.5) | O16: =IF(OR(M16="",N16=""),"",_xlfn.CEILING.MATH((N16-M16-(MEDIAN(N16,"13:00","12:00")-MEDIAN(M16,"13:00","12:00"))-(MEDIAN(N16,"16:30","16:00")-MEDIAN(M16,"16:30","16:00"))),"0:30")*24)
B17: =IFERROR(__xludf.DUMMYFUNCTION("IFERROR(REGEXEXTRACT(A17,""\| (.+)$""),"""") "),"") | G17: =IF(OR(E17="",F17=""),"",E17*F17) | K17: =IF(OR(E17="",F17=""),"",(E17*F17)/7.5)
A18: 총수량 | C18: =SUM(C8:C17) -> 2232 | D18: =SUM(D8:D17) -> 186 | E18: =SUM(E8:E17) -> 7.5 | F18: =IFERROR(G18/E18, 0) -> 2.6 | G18: =SUM(G8:G17) -> 19.5 | K18: =SUM(K8:K14) -> 2.6
A20: ■ 라벨부착작업
A21: 품명 | B21: 용량/규격 | C21: 수량 | D21: 박스 | E21: 작업시간 | F21: 투입인원수 | G21: 총작업시간 | H21: LINE/구분 | I21: 비고(LOT/NO) | J21: 카테고리 | K21: 작업공수 | M21: 시작 | N21: 끝 | O21: 작업시간
A22: DA020669 / 프로텍 브레이크액 DOT-4+ LV 1L 라벨 | 81*111 | B22: =IFERROR(__xludf.DUMMYFUNCTION("IFERROR(REGEXEXTRACT(A22,""\| (.+)$""),"""") "),"81*111") -> 81*111 | C22: 1912 | E22: 3 | F22: 2 | G22: =IF(OR(E22="",F22=""),"",E22*F22) -> 6 | H22: 자동B | J22: 브레이크액 | K22: =IF(OR(E22="",F22=""),"",(E22*F22)/7.5) -> 0.8 | L22: 정화순, 김백철 | O22: =IF(OR(M22="",N22=""),"",_xlfn.CEILING.MATH((N22-M22-(MEDIAN(N22,"13:00","12:00")-MEDIAN(M22,"13:00","12:00"))-(MEDIAN(N22,"16:30","16:00")-MEDIAN(M22,"16:30","16:00"))),"0:30")*24)
A23: DO020101 / 썸오일 100% 합성엔진오일 10W-40 4L 라벨 리뉴얼 | 108*160 | B23: =IFERROR(__xludf.DUMMYFUNCTION("IFERROR(REGEXEXTRACT(A23,""\| (.+)$""),"""") "),"108*160") -> 108*160 | C23: 96 | E23: 1 | F23: 1 | G23: =IF(OR(E23="",F23=""),"",E23*F23) -> 1 | H23: 수동 | J23: 엔진오일 | K23: =IF(OR(E23="",F23=""),"",(E23*F23)/7.5) -> 0.13333333 | L23: 김백철 | O23: =IF(OR(M23="",N23=""),"",_xlfn.CEILING.MATH((N23-M23-(MEDIAN(N23,"13:00","12:00")-MEDIAN(M23,"13:00","12:00"))-(MEDIAN(N23,"16:30","16:00")-MEDIAN(M23,"16:30","16:00"))),"0:30")*24)
B24: =IFERROR(__xludf.DUMMYFUNCTION("IFERROR(REGEXEXTRACT(A24,""\| (.+)$""),"""") "),"") | G24: =IF(OR(E24="",F24=""),"",E24*F24) | K24: =IF(OR(E24="",F24=""),"",(E24*F24)/7.5) | O24: =IF(OR(M24="",N24=""),"",_xlfn.CEILING.MATH((N24-M24-(MEDIAN(N24,"13:00","12:00")-MEDIAN(M24,"13:00","12:00"))-(MEDIAN(N24,"16:30","16:00")-MEDIAN(M24,"16:30","16:00"))),"0:30")*24)
B25: =IFERROR(__xludf.DUMMYFUNCTION("IFERROR(REGEXEXTRACT(A25,""\| (.+)$""),"""") "),"") | G25: =IF(OR(E25="",F25=""),"",E25*F25) | K25: =IF(OR(E25="",F25=""),"",(E25*F25)/7.5) | O25: =IF(OR(M25="",N25=""),"",_xlfn.CEILING.MATH((N25-M25-(MEDIAN(N25,"13:00","12:00")-MEDIAN(M25,"13:00","12:00"))-(MEDIAN(N25,"16:30","16:00")-MEDIAN(M25,"16:30","16:00"))),"0:30")*24)
B26: =IFERROR(__xludf.DUMMYFUNCTION("IFERROR(REGEXEXTRACT(A26,""\| (.+)$""),"""") "),"") | G26: =IF(OR(E26="",F26=""),"",E26*F26) | K26: =IF(OR(E26="",F26=""),"",(E26*F26)/7.5) | O26: =IF(OR(M26="",N26=""),"",_xlfn.CEILING.MATH((N26-M26-(MEDIAN(N26,"13:00","12:00")-MEDIAN(M26,"13:00","12:00"))-(MEDIAN(N26,"16:30","16:00")-MEDIAN(M26,"16:30","16:00"))),"0:30")*24)
A27: 총수량 | C27: =SUM(C22:C26) -> 2008 | D27: =SUM(D22:D26) -> 0 | E27: =SUM(E22:E26) -> 4 | F27: =IFERROR(G27/E27, 0) -> 1.75 | G27: =SUM(G22:G26) -> 7 | K27: =SUM(K22:K26) -> 0.93333333
A29: ■ 원액생산작업
A30: 품명 | B30: 용량/규격 | C30: 수량 | D30: 포장 | E30: 작업시간 | F30: 투입인원수 | G30: 총작업시간 | H30: LINE/구분 | I30: 비고(LOT/NO) | J30: 카테고리 | K30: 작업공수
A31: 5AA40008 / ODM 5W30 | B31: L | C31: 2540 | D31: TOTE | E31: 3 | F31: 2 | G31: =IF(OR(E31="",F31=""),"",E31*F31) -> 6 | I31: G260915-021 | J31: 엔진오일 | K31: =IF(OR(E31="",F31=""),"",(E31*F31)/7.5) -> 0.8
A32: 5AA40021 / GT formula 엔진오일 PAO 5W30 | B32: L | C32: 1400 | D32: TOTE | E32: 2 | F32: 2 | G32: =IF(OR(E32="",F32=""),"",E32*F32) -> 4 | I32: G260915-022 | J32: 엔진오일 | K32: =IF(OR(E32="",F32=""),"",(E32*F32)/7.5) -> 0.53333333
A33: 5AA40019 / ODM 5W30 PAO | B33: L | C33: 1000 | D33: TOTE | E33: 1 | F33: 2 | G33: =IF(OR(E33="",F33=""),"",E33*F33) -> 2 | I33: G260915-023 | J33: 엔진오일 | K33: =IF(OR(E33="",F33=""),"",(E33*F33)/7.5) -> 0.26666667
G34: =IF(OR(E34="",F34=""),"",E34*F34) | K34: =IF(OR(E34="",F34=""),"",(E34*F34)/7.5)
G35: =IF(OR(E35="",F35=""),"",E35*F35) | K35: =IF(OR(E35="",F35=""),"",(E35*F35)/7.5)
A36: 총수량 | C36: =SUM(C31:C35) -> 4940 | E36: =SUM(E28:E35) -> 6 | F36: =IFERROR(G36/E36, 0) -> 3.1666667 | G36: =SUM(G26:G35) -> 19 | K36: =SUM(K31:K35) -> 1.6
A38: ■ 출고내역
A39: 품명 | B39: 용량/규격 | C39: 수량 | D39: 박스 | E39: 거래처 | G39: 확인자 | H39: 운송 | I39: 비고
A40: 2AA40032 / 디알텍 100%합성엔진오일 5W30 | 1L | B40: =IFERROR(__xludf.DUMMYFUNCTION("IFERROR(REGEXEXTRACT(A40,""\| (.+)$""),"""") "),"1L") -> 1L | C40: 1440 | D40: 120 | E40: 드림컴퍼니 | G40: 윤경용 | H40: 용차 | I40: 운송비154,000원(VAT포함)
A41: 2AA40041 / 스탠다드 100%합성엔진오일 5W30 | 1L | B41: =IFERROR(__xludf.DUMMYFUNCTION("IFERROR(REGEXEXTRACT(A41,""\| (.+)$""),"""") "),"1L") -> 1L | C41: 1440 | D41: 120 | E41: 드림컴퍼니 | G41: 윤경용 | H41: 용차
B42: =IFERROR(__xludf.DUMMYFUNCTION("IFERROR(REGEXEXTRACT(A42,""\| (.+)$""),"""") "),"")
B43: =IFERROR(__xludf.DUMMYFUNCTION("IFERROR(REGEXEXTRACT(A43,""\| (.+)$""),"""") "),"")
B47: =IFERROR(__xludf.DUMMYFUNCTION("IFERROR(REGEXEXTRACT(A47,""\| (.+)$""),"""") "),"")
A48: 총수량 | C48: =SUM(C40:C47) -> 2880
...

Sheet 0914
I1: 담당 | J1: 검토 | K1: 확인
A2: (김포)생산공급망 업무일지 | I2: 최용화 | J2: 윤경용 | N2: 초록색상 지우기와 기재 금지
A4: 날짜 | B4: 46279
A6: ■ 제품포장작업
A7: 품명 | B7: 용량/규격 | C7: 수량 | D7: 박스 | E7: 작업시간 | F7: 투입인원수 | G7: 총작업시간 | H7: LINE/구분 | I7: 비고(LOT/NO) | J7: 카테고리 | K7: 작업공수 | L7: 작업자 | M7: 시작 | N7: 끝 | O7: 작업시간
A8: 1AH40001 / 프로텍 프리미엄 브레이크액 DOT-4+ | 1L | B8: =IFERROR(__xludf.DUMMYFUNCTION("IFERROR(REGEXEXTRACT(A8,""\| (.+)$""),"""") "),"1L") -> 1L | C8: 1032 | D8: 86 | E8: 4 | F8: 3 | G8: =IF(OR(E8="",F8=""),"",E8*F8) -> 12 | H8: 수동3 | I8: 260910 | J8: 브레이크액 | K8: =IF(OR(E8="",F8=""),"",(E8*F8)/7.5) -> 1.6 | L8: 정화순, 김백철, 김세중 | O8: =IF(OR(M8="",N8=""),"",_xlfn.CEILING.MATH((N8-M8-(MEDIAN(N8,"13:00","12:00")-MEDIAN(M8,"13:00","12:00"))-(MEDIAN(N8,"16:30","16:00")-MEDIAN(M8,"16:30","16:00"))),"0:30")*24)
A9: 1AH40001 / 프로텍 프리미엄 브레이크액 DOT-4+ | 1L | B9: =IFERROR(__xludf.DUMMYFUNCTION("IFERROR(REGEXEXTRACT(A9,""\| (.+)$""),"""") "),"1L") -> 1L | C9: 360 | D9: 30 | E9: 1 | F9: 2 | G9: =IF(OR(E9="",F9=""),"",E9*F9) -> 2 | H9: 수동3 | I9: 260910 | J9: 브레이크액 | K9: =IF(OR(E9="",F9=""),"",(E9*F9)/7.5) -> 0.26666667 | L9: 정화순, 김세중 | O9: =IF(OR(M9="",N9=""),"",_xlfn.CEILING.MATH((N9-M9-(MEDIAN(N9,"13:00","12:00")-MEDIAN(M9,"13:00","12:00"))-(MEDIAN(N9,"16:30","16:00")-MEDIAN(M9,"16:30","16:00"))),"0:30")*24)
A10: 1AH40002 / 프로텍 프리미엄 브레이크액 DOT-4+ LV | 1L | B10: =IFERROR(__xludf.DUMMYFUNCTION("IFERROR(REGEXEXTRACT(A10,""\| (.+)$""),"""") "),"1L") -> 1L | C10: 300 | D10: 25 | E10: 1.5 | F10: 2 | G10: =IF(OR(E10="",F10=""),"",E10*F10) -> 3 | H10: 수동3 | I10: 260914 | J10: 브레이크액 | K10: =IF(OR(E10="",F10=""),"",(E10*F10)/7.5) -> 0.4 | L10: 정화순, 김세중 | O10: =IF(OR(M10="",N10=""),"",_xlfn.CEILING.MATH((N10-M10-(MEDIAN(N10,"13:00","12:00")-MEDIAN(M10,"13:00","12:00"))-(MEDIAN(N10,"16:30","16:00")-MEDIAN(M10,"16:30","16:00"))),"0:30")*24)
A11: 1AH40002 / 프로텍 프리미엄 브레이크액 DOT-4+ LV | 1L | B11: =IFERROR(__xludf.DUMMYFUNCTION("IFERROR(REGEXEXTRACT(A11,""\| (.+)$""),"""") "),"1L") -> 1L | C11: 348 | D11: 29 | E11: 1 | F11: 3 | G11: =IF(OR(E11="",F11=""),"",E11*F11) -> 3 | H11: 수동3 | I11: 260914 | J11: 브레이크액 | K11: =IF(OR(E11="",F11=""),"",(E11*F11)/7.5) -> 0.4 | L11: 정화순, 김백철, 김세중 | O11: =IF(OR(M11="",N11=""),"",_xlfn.CEILING.MATH((N11-M11-(MEDIAN(N11,"13:00","12:00")-MEDIAN(M11,"13:00","12:00"))-(MEDIAN(N11,"16:30","16:00")-MEDIAN(M11,"16:30","16:00"))),"0:30")*24)
B12: =IFERROR(__xludf.DUMMYFUNCTION("IFERROR(REGEXEXTRACT(A12,""\| (.+)$""),"""") "),"") | G12: =IF(OR(E12="",F12=""),"",E12*F12) | K12: =IF(OR(E12="",F12=""),"",(E12*F12)/7.5) | O12: =IF(OR(M12="",N12=""),"",_xlfn.CEILING.MATH((N12-M12-(MEDIAN(N12,"13:00","12:00")-MEDIAN(M12,"13:00","12:00"))-(MEDIAN(N12,"16:30","16:00")-MEDIAN(M12,"16:30","16:00"))),"0:30")*24)
B13: =IFERROR(__xludf.DUMMYFUNCTION("IFERROR(REGEXEXTRACT(A13,""\| (.+)$""),"""") "),"") | G13: =IF(OR(E13="",F13=""),"",E13*F13) | K13: =IF(OR(E13="",F13=""),"",(E13*F13)/7.5) | O13: =IF(OR(M13="",N13=""),"",_xlfn.CEILING.MATH((N13-M13-(MEDIAN(N13,"13:00","12:00")-MEDIAN(M13,"13:00","12:00"))-(MEDIAN(N13,"16:30","16:00")-MEDIAN(M13,"16:30","16:00"))),"0:30")*24)
B14: =IFERROR(__xludf.DUMMYFUNCTION("IFERROR(REGEXEXTRACT(A14,""\| (.+)$""),"""") "),"") | G14: =IF(OR(E14="",F14=""),"",E14*F14) | K14: =IF(OR(E14="",F14=""),"",(E14*F14)/7.5) | O14: =IF(OR(M14="",N14=""),"",_xlfn.CEILING.MATH((N14-M14-(MEDIAN(N14,"13:00","12:00")-MEDIAN(M14,"13:00","12:00"))-(MEDIAN(N14,"16:30","16:00")-MEDIAN(M14,"16:30","16:00"))),"0:30")*24)
B15: =IFERROR(__xludf.DUMMYFUNCTION("IFERROR(REGEXEXTRACT(A15,""\| (.+)$""),"""") "),"") | G15: =IF(OR(E15="",F15=""),"",E15*F15) | K15: =IF(OR(E15="",F15=""),"",(E15*F15)/7.5) | O15: =IF(OR(M15="",N15=""),"",_xlfn.CEILING.MATH((N15-M15-(MEDIAN(N15,"13:00","12:00")-MEDIAN(M15,"13:00","12:00"))-(MEDIAN(N15,"16:30","16:00")-MEDIAN(M15,"16:30","16:00"))),"0:30")*24)
B16: =IFERROR(__xludf.DUMMYFUNCTION("IFERROR(REGEXEXTRACT(A16,""\| (.+)$""),"""") "),"") | G16: =IF(OR(E16="",F16=""),"",E16*F16) | K16: =IF(OR(E16="",F16=""),"",(E16*F16)/7.5) | O16: =IF(OR(M16="",N16=""),"",_xlfn.CEILING.MATH((N16-M16-(MEDIAN(N16,"13:00","12:00")-MEDIAN(M16,"13:00","12:00"))-(MEDIAN(N16,"16:30","16:00")-MEDIAN(M16,"16:30","16:00"))),"0:30")*24)
B17: =IFERROR(__xludf.DUMMYFUNCTION("IFERROR(REGEXEXTRACT(A17,""\| (.+)$""),"""") "),"") | G17: =IF(OR(E17="",F17=""),"",E17*F17) | K17: =IF(OR(E17="",F17=""),"",(E17*F17)/7.5)
A18: 총수량 | C18: =SUM(C8:C17) -> 2040 | D18: =SUM(D8:D17) -> 170 | E18: =SUM(E8:E17) -> 7.5 | F18: =IFERROR(G18/E18, 0) -> 2.6666667 | G18: =SUM(G8:G17) -> 20 | K18: =SUM(K8:K14) -> 2.6666667
A20: ■ 라벨부착작업
A21: 품명 | B21: 용량/규격 | C21: 수량 | D21: 박스 | E21: 작업시간 | F21: 투입인원수 | G21: 총작업시간 | H21: LINE/구분 | I21: 비고(LOT/NO) | J21: 카테고리 | K21: 작업공수 | M21: 시작 | N21: 끝 | O21: 작업시간
A22: DA020669 / 프로텍 브레이크액 DOT-4+ LV 1L 라벨 | 81*111 | B22: =IFERROR(__xludf.DUMMYFUNCTION("IFERROR(REGEXEXTRACT(A22,""\| (.+)$""),"""") "),"81*111") -> 81*111 | C22: 1808 | E22: 2.5 | F22: 2 | G22: =IF(OR(E22="",F22=""),"",E22*F22) -> 5 | H22: 자동B | J22: 브레이크액 | K22: =IF(OR(E22="",F22=""),"",(E22*F22)/7.5) -> 0.66666667 | L22: 윤경용, 김백철 | O22: =IF(OR(M22="",N22=""),"",_xlfn.CEILING.MATH((N22-M22-(MEDIAN(N22,"13:00","12:00")-MEDIAN(M22,"13:00","12:00"))-(MEDIAN(N22,"16:30","16:00")-MEDIAN(M22,"16:30","16:00"))),"0:30")*24)
B23: =IFERROR(__xludf.DUMMYFUNCTION("IFERROR(REGEXEXTRACT(A23,""\| (.+)$""),"""") "),"") | G23: =IF(OR(E23="",F23=""),"",E23*F23) | K23: =IF(OR(E23="",F23=""),"",(E23*F23)/7.5) | O23: =IF(OR(M23="",N23=""),"",_xlfn.CEILING.MATH((N23-M23-(MEDIAN(N23,"13:00","12:00")-MEDIAN(M23,"13:00","12:00"))-(MEDIAN(N23,"16:30","16:00")-MEDIAN(M23,"16:30","16:00"))),"0:30")*24)
B24: =IFERROR(__xludf.DUMMYFUNCTION("IFERROR(REGEXEXTRACT(A24,""\| (.+)$""),"""") "),"") | G24: =IF(OR(E24="",F24=""),"",E24*F24) | K24: =IF(OR(E24="",F24=""),"",(E24*F24)/7.5) | O24: =IF(OR(M24="",N24=""),"",_xlfn.CEILING.MATH((N24-M24-(MEDIAN(N24,"13:00","12:00")-MEDIAN(M24,"13:00","12:00"))-(MEDIAN(N24,"16:30","16:00")-MEDIAN(M24,"16:30","16:00"))),"0:30")*24)
B25: =IFERROR(__xludf.DUMMYFUNCTION("IFERROR(REGEXEXTRACT(A25,""\| (.+)$""),"""") "),"") | G25: =IF(OR(E25="",F25=""),"",E25*F25) | K25: =IF(OR(E25="",F25=""),"",(E25*F25)/7.5) | O25: =IF(OR(M25="",N25=""),"",_xlfn.CEILING.MATH((N25-M25-(MEDIAN(N25,"13:00","12:00")-MEDIAN(M25,"13:00","12:00"))-(MEDIAN(N25,"16:30","16:00")-MEDIAN(M25,"16:30","16:00"))),"0:30")*24)
B26: =IFERROR(__xludf.DUMMYFUNCTION("IFERROR(REGEXEXTRACT(A26,""\| (.+)$""),"""") "),"") | G26: =IF(OR(E26="",F26=""),"",E26*F26) | K26: =IF(OR(E26="",F26=""),"",(E26*F26)/7.5) | O26: =IF(OR(M26="",N26=""),"",_xlfn.CEILING.MATH((N26-M26-(MEDIAN(N26,"13:00","12:00")-MEDIAN(M26,"13:00","12:00"))-(MEDIAN(N26,"16:30","16:00")-MEDIAN(M26,"16:30","16:00"))),"0:30")*24)
A27: 총수량 | C27: =SUM(C22:C26) -> 1808 | D27: =SUM(D22:D26) -> 0 | E27: =SUM(E22:E26) -> 2.5 | F27: =IFERROR(G27/E27, 0) -> 2 | G27: =SUM(G22:G26) -> 5 | K27: =SUM(K22:K26) -> 0.66666667
A29: ■ 원액생산작업
A30: 품명 | B30: 용량/규격 | C30: 수량 | D30: 포장 | E30: 작업시간 | F30: 투입인원수 | G30: 총작업시간 | H30: LINE/구분 | I30: 비고(LOT/NO) | J30: 카테고리 | K30: 작업공수
G31: =IF(OR(E31="",F31=""),"",E31*F31) | K31: =IF(OR(E31="",F31=""),"",(E31*F31)/7.5)
G32: =IF(OR(E32="",F32=""),"",E32*F32) | K32: =IF(OR(E32="",F32=""),"",(E32*F32)/7.5)
G33: =IF(OR(E33="",F33=""),"",E33*F33) | K33: =IF(OR(E33="",F33=""),"",(E33*F33)/7.5)
G34: =IF(OR(E34="",F34=""),"",E34*F34) | K34: =IF(OR(E34="",F34=""),"",(E34*F34)/7.5)
G35: =IF(OR(E35="",F35=""),"",E35*F35) | K35: =IF(OR(E35="",F35=""),"",(E35*F35)/7.5)
A36: 총수량 | C36: =SUM(C31:C35) -> 0 | E36: =SUM(E28:E35) -> 0 | F36: =IFERROR(G36/E36, 0) -> 0 | G36: =SUM(G26:G35) -> 5 | K36: =SUM(K31:K35) -> 0
A38: ■ 출고내역
A39: 품명 | B39: 용량/규격 | C39: 수량 | D39: 박스 | E39: 거래처 | G39: 확인자 | H39: 운송 | I39: 비고
B40: =IFERROR(__xludf.DUMMYFUNCTION("IFERROR(REGEXEXTRACT(A40,""\| (.+)$""),"""") "),"")
B41: =IFERROR(__xludf.DUMMYFUNCTION("IFERROR(REGEXEXTRACT(A41,""\| (.+)$""),"""") "),"")
B42: =IFERROR(__xludf.DUMMYFUNCTION("IFERROR(REGEXEXTRACT(A42,""\| (.+)$""),"""") "),"")
B43: =IFERROR(__xludf.DUMMYFUNCTION("IFERROR(REGEXEXTRACT(A43,""\| (.+)$""),"""") "),"")
B47: =IFERROR(__xludf.DUMMYFUNCTION("IFERROR(REGEXEXTRACT(A47,""\| (.+)$""),"""") "),"")
A48: 총수량 | C48: =SUM(C40:C47) -> 0
...

Sheet 0911
I1: 담당 | J1: 검토 | K1: 확인
A2: (김포)생산공급망 업무일지 | I2: 최용화 | J2: 윤경용 | N2: 초록색상 지우기와 기재 금지
A4: 날짜 | B4: 46276
A6: ■ 제품포장작업
A7: 품명 | B7: 용량/규격 | C7: 수량 | D7: 박스 | E7: 작업시간 | F7: 투입인원수 | G7: 총작업시간 | H7: LINE/구분 | I7: 비고(LOT/NO) | J7: 카테고리 | K7: 작업공수 | L7: 작업자 | M7: 시작 | N7: 끝 | O7: 작업시간
